Workbook

Sheet ĐỔI LINK IMPORTRANGE
A1: BẢNG ĐỔI LINK IMPORTRANGE — điền cột B rồi chạy "2. Bắt đầu thay thế"
A3: Link/Key GỐC (tự quét — đừng sửa) | B3: Link/Key THAY THẾ (bạn điền) | C3: Số ô đang dùng | D3: Vị trí (sheet!ô)
A4: 185W47XpkC4eZ2FKSbi1DoXxxlcyxtBBS9e7jlxfUMtE | B4: 185W47XpkC4eZ2FKSbi1DoXxxlcyxtBBS9e7jlxfUMtE | C4: 1 | D4: 1. DATA CHUNG!A1
A5: 1QhJTRnGJtBKZs2tC-q6M0AHpmJHVvWU0XHZcR72b8nM | B5: 185W47XpkC4eZ2FKSbi1DoXxxlcyxtBBS9e7jlxfUMtE | C5: 2 | D5: 2. DATA NL, VTBB!A1, DANH MUC ICARE!A2

Sheet 0.Ngân Hàng
A1: Tên TK thụ hưởng: | B1: Số TK thụ hưởng: | C1: Ngân hàng/Chi nhánh:
A2: CÔNG TY CỔ PHẦN VIỆT MỸ CẦN THƠ | B2: 111000293216 | C2: Vietcombank - CN Cần Thơ
A3: CÔNG TY TNHH THƯƠNG MẠI HIỀN PHAN LONG AN | B3: 1027554287 | C3: Ngân hàng Vietcombank
A4: CHI NHÁNH CÔNG TY TNHH SGN MIỀN NAM | B4: 37397989 | C4: Ngân hàng Techcombank
A5: CÔNG TY TNHH HOÁ SINH NTK | B5: 118002908288 | C5: Ngân Hàng Vietinbank - CN 4 - PGD Văn Thánh
A6: CÔNG TY TNHH VĨNH NAM ANH | B6: 3180355787 | C6: Ngân hàng Đầu Tư Và Phát Triển Việt Nam CN Hóc Môn
A7: CÔNG TY TNHH THƯƠNG MẠI HÓA CHẤT NAM BÌNH | B7: 80136159 | C7: NH TMCP Á Châu ( ACB Bank )
A8: CÔNG TY CỔ PHẦN CÔNG NGHỆ AQUADELTA | B8: 118002852200 | C8: Ngân hàng Vietinbank CN Cần Thơ
A9: CÔNG TY TNHH MÁY VÀ HÓA CHẤT TOÀN CẦU | B9: 6686333888 | C9: Ngân hàng TMCP Quân Đội (MB) Chi nhánh Hòa Lạc
A10: CÔNG TY TNHH NGUYÊN LIỆU NÔNG NGHIỆP MEKONG | B10: 209120169 | C10: Ngân hàng TMCP Á Châu - CN Sài Gòn
A11: CÔNG TY TNHH THỊNH PHÁT VI NA | B11: 60005959201 | C11: Ngân Hàng Sacombank
A12: CÔNG TY CỔ PHẦN MẠNH ĐAN | B12: 110637556789 | C12: Ngân hàng Vietinbank – CN Thủ Đức - PGD Metro
A13: CÔNG TY TNHH VẬT TƯ NÔNG NGHIỆP MIA | B13: 110634956789 | C13: Ngân hàng Vietinbank
... A38: CÔNG TY TNHH SẢN XUẤT BAO BÌ ĐÔNG BẮC | B38: 34560036 | C38: Ngân hàng TMCP Á Châu (ACB) - CN: Hóc Môn, Tp.HCM
A39: CÔNG TY CỔ PHẦN MEKONG LOGISTICS

Sheet MỤC LỤC-HƯỚNG DẪN
A1: STT | B1: TÊN | C1: PHÂN LOẠI | D1: MỤC TIÊU | E1: NỘI DUNG CHI TIẾT | F1: LINK | G1: Gợi ý góp ý | H1: Công việc cần thu mua xem | I1: Nhận xét từ NSPT Thu mua | J1: HƯỚNG DẪN
A2: 1 | B2: DATA CHUNG | C2: Chỉ xem | D2: Lấy dữ liệu đầu vào từ 1. DATA DỮ LIỆU ĐẦU VÀO TM | E2: Các dữ liệu liên quan đến NCC, NSPT, Kho nhận,.. các dữ liệu cố định sử dụng chọn trong sheet "THU MUA MS QUYÊN" - Bổ sung dữ liệu nếu muốn ( ví dụ: Thêm nhân sự Mr Hậu tại cột NSPT) | F2: 1. DATA CHUNG | G2: Data có thể chưa đúng, nhờ anh chị kiểm tra lại xem ngày quy định/loại vtbb, tên NCC, tên kho nhận,... | H2: Rà soát lại các danh mục về Ngày quy định, Loại VTBB, Tên NCC và Kho nhận,..... xem đã chuẩn xác chưa | I2: - Data 1, bổ sung thông tin, (ngưng giao dịch không nhập): * Các NCC/Kho nhận/ ĐV vận chuyển + Mr Hậu bổ sung NCC VTBB + Ms Quyên/Ms Dung/Mr Tiên phụ trách NCC nào thì bổ sung vào nếu thiếu => Deadline: Hậu_hết ngày 7/3; Ms Quyên (NL trong nước) 10/3; Ms Dung (nhãn mác) 9/3; Mr Tiên 10/3. * Các thời gian quy định: cập nhật ngày quy định và phân loại - PHÂN LOẠI VTBB sẽ là cick chọn theo data có sẵn (nhãn, nhãn túi, túi trục,...) để chạy ngày quy định hợp lý hơn
A3: 2 | B3: DATA NL, VTBB | C3: Chỉ xem | D3: Lấy dữ liệu đầu vào | E3: Dữ liệu tổng VTBB - lấy dữ liệu từ Ms Ly Dữ liệu tổng NL - lấy dữ liệu từ Ms Ngân (đang đồng bộ ktoan) | F3: 2. DATA NL, VTBB | G3: Này chạy công thức từ Data Ms Ly và Ms Ngân, nên anh chị có thể bỏ qua
A4: 3 | B4: KHẢO SÁT, LẤY MẪU ĐÁNH GIÁ NCC | C4: Nhập liệu | D4: Dùng cho công việc khảo sát, đánh giá NCC & lưu trữ thông tin nội bộ | E4: - Xoay quanh thông tin NCC | F4: 3. KHẢO SÁT, LẤY MẪU ĐÁNH GIÁ NCC | J4: - Chụp hình/ xuất PDF gửi trình duyệt vào group GVSX từng cá nhân - QL duyệt + yêu cầu trên sheet
A5: 4 | B5: KHẢO SÁT, LẤY MẪU ĐÁNH GIÁ SP | C5: Nhập liệu | D5: Dùng cho công việc khảo sát, đánh giá sản phẩm & lưu trữ thông tin nội bộ | E5: - Xoay quanh thông tin Sản phẩm. các thông tin NCC tự động chạy từ mục 2.1 qua | F5: 4. KHẢO SÁT, LẤY MẪU ĐÁNH GIÁ SP | J5: - Chụp hình/ xuất PDF gửi trình duyệt vào group GVSX từng cá nhân - QL duyệt + yêu cầu trên sheet
A6: 5 | B6: QUY ĐỔI ĐVT NCC | C6: Nhập liệu | D6: Quy đổi về cùng ĐVT dùng trong đối chiếu giá giữa các NCC | E6: - Công cụ hỗ trợ tính quy đổi ĐVT của sản phẩm từ NCC qua ĐVT công ty. Và giá trên ĐVT đã quy đổi | F6: 5. QUY ĐỔI ĐVT NCC
A7: 6 | B7: TIẾN ĐỘ MUA HÀNG | C7: Nhập liệu | D7: Nhập liệu và lưu trữ thông tin nội bộ | E7: - Thu mua nhận thông tin từ các bộ phận, nhập/chọn vào các trường tương ứng của cột/dòng tại Sheet THU MUA MS QUYÊN. - Các trường dữ liệu có công thức sẽ tự động chạy thông tin cho bạn, đảm bảo tính chính xác bạn kiểm tra lại thông tin, nghi ngờ sai dữ liệu thì hỏi lại Quản lý tồn kho VTBB/NL - Trường hợp giao nhiều lần: Bạn sẽ copy, thêm và dán dòng mới, sau đó chỉ cần nhập số lần nhận (tại cột X) và các thông tin liên quan đến lần giao đó như số lượng, kho nhận. Tương tự khi KD yêu cầu chia thành 2 đợt nhận. - Trường hợp HỦY/NGƯNG, bạn cập nhật tại cột trạng thái cùng ghi chú lý do cột ghi chú, mục đích lưu lại lịch sử khi cần tra cứu. - Lưu ý: không được hợp nhất dòng, ô, cột sẽ ảnh hưởng đến báo cáo tự động | F7: 6. TIẾN ĐỘ MUA HÀNG | G7: Mỗi NS thu mua sẽ là 1 link Drive riêng Các tiêu đề cột, còn thiếu dữ liệu nào không? Từ sheet này sẽ cho ra các báo cáo tự động => Anh/Chị muốn bỏ báo cáo nào hay giữ lại hết, thêm báo cáo loại nào ? | H7: Các trường dữ liệu hiện tại đã đủ để lên một đơn hàng hoàn chỉnh chưa? Có cần bổ sung cột nào không | I7: - Tiêu đề không in hoa - BP Đặt Hàng/ Cá Nhân - Tên tiêu đề điều chỉnh ( VTBB/NL) Điều chỉnh thứ tự cột: - Mr Tiên: Số lượng yêu cầu trước cột số lượng đặt và cột số kiện hàng gần nhau - Báo cáo giải thích chi tiết ai cần thì để báo cáo xem, Từ ngày tiếp nhận +3 ngày đến ngày đó thông báo KD - Báo cáo cuối ngày trích báo cáo cho BP yêu cầu / Cho Kho Dego 15h - Lấy dữ liệu copy cũ qua từ ngày 1/1/2026 NSPT
A8: 7 | B8: PO GỬI NHÀ CUNG CẤP | C8: Nhập mã | D8: Tạo đơn đặt hàng gửi NCC | E8: - Đơn đặt hàng, nhập các dữ liệu cần thiết thông tin tự động điền | F8: 7. PO GỬI NCC | J8: - Copy mã DMH, in trình ký QL=> gửi NCC
A9: 8 | B9: THEO DÕI CHI NCC | C9: Nhập liệu | D9: Ghi nhận thông tin về việc dự chi, tạm ứng, chi thực tế cho NCC Tổng hợp báo cáo dự chi, tạm ứng, thực chi, hoàn ứng cho từng đơn hàng theo từng lần nhận" | F9: 8. THEO DÕI CHI NC | H9: Từ dữ liệu đầu vào sheet '1. Thu mua ms Quyên', em đang cho chạy ra 6 báo cáo tự động. Anh/Chị xem có cần thêm/bớt loại báo cáo nào để phục vụ quản lý tốt hơn không ạ | J9: - Nhập đầy đủ phát sinh - Nếu không khớp với giấy thanh toán thì không được duyệt
A10: 9 | B10: ĐÁNH GIÁ HỢP ĐỒNG | C10: Nhập liệu | D10: Đánh giá sơ bộ Hợp đồng và ghi chú lại các vấn đề cần lưu ý | F10: 9. ĐÁNH GIÁ HỢP ĐỒNG | J10: Nhập và in, ký trình QL kèm: - Hợp đồng nguyên bản - Hợp đồng sau sửa
A11: 10 | B11: ĐỐI CHIẾU CÔNG NỢ | C11: Nhập liệu | D11: Nhập liệu và thực hiện đối chiếu công nợ định kỳ với NCC theo quy định | F11: 10. ĐỐI CHIẾU CÔNG NỢ | J11: - Nhận BB đối chiếu từ NCC - Thực hiện đối chiếu phát sinh tăng, giảm với dữ liệu Misa => Nhập lên Drive và in trình ký QL trước ngày 12 hằng tháng Phân loại theo nhóm: 1 Công nợ NCC 2.10 Lãi trả chậm
A12: 11 | B12: BÁO CÁO TIẾN ĐỘ ĐƠN MUA HÀNG | C12: Chỉ xem | D12: Kiểm soát tiến độ đơn hàng | E12: - Từ sheet THU MUA MS QUYÊN, dữ liệu chạy tự động báo cáo gồm thời gian đặt hàng, mua hàng, số lần nhận hàng, số lần, ghi chú, trạng thái đơn hàng... - Có cảnh báo Trước 3 ngày/trễ hẹn : + Ngày NCC dự kiến giao + Ngày KD yêu cầu + Đã nhận hàng chưa có hóa đơn => thông báo đến các bộ phận Kho, KD, nộp chứng từ kế toán Ngoài lọc thủ công có dòng tra cứu nhanh trả kết quả, nhập Đơn Misa hiển thị ngày giao (mục đích xác định ngày nhận hàng nếu các bộ phận hỏi) | F12: 11. BÁO CÁO TIẾN ĐỘ ĐƠN MUA HÀNG | J12: Làm theo hướng dẫn trên sheet
A13: 12 | B13: BÁO CÁO NSPT | C13: Chỉ xem | D13: Thống kê số đơn hàng xử lý và tiến độ ĐH trên từng nhân sự | E13: - Từ sheet THU MUA MS QUYÊN, dữ liệu chạy tự động báo cáo gồm các thông tin liên quan: + Tổng số đơn hàng mà nhân sự thu mua + Có bao nhiêu đơn trễ tiến độ (theo ngày quy định) + Tỷ lệ trễ | F13: 12. BÁO CÁO NSPT | J13: Làm theo hướng dẫn trên sheet
A14: 13 | B14: BÁO CÁO PHÂN LOẠI VTBB/NL | C14: Chỉ xem | D14: Tần suất mua các loại VTBB/NL + chi phí | E14: - Từ sheet THU MUA MS QUYÊN, dữ liệu chạy tự động báo cáo gồm các thông tin liên quan: + Tần suất mua hàng của loại VTBB/NL đó trong 1 tháng/năm + Chi phí mua loại VTBB/NL trong 1 tháng/năm | F14: 13. BÁO CÁO PHÂN LOẠI VTBB/NL | J14: Làm theo hướng dẫn trên sheet
A15: 14 | B15: BÁO CÁO NCC | C15: Chỉ xem | D15: Tần suất giao dịch và tỷ lệ trễ đơn trên từng NCC | E15: - Từ sheet THU MUA MS QUYÊN, dữ liệu chạy tự động báo cáo gồm các thông tin liên quan : + Tần xuất giao dịch đối với NCC trong tháng trong năm + Có bao nhiêu đơn NCC trễ tiến độ (theo ngày NCC dự kiến so với ngày nhận hàng thực tế) + Tỷ lệ trễ | F15: 14. BÁO CÁO NCC | J15: Làm theo hướng dẫn trên sheet
A16: 15 | B16: BÁO CÁO BỘ PHẬN | C16: Chỉ xem | D16: Tấn suất đặt hàng của các BP yêu cầu và tỷ lệ gấp so với thời gian quy định | E16: - Từ sheet THU MUA MS QUYÊN, dữ liệu chạy tự động báo cáo gồm các thông tin liên quan đến chành và giao hàng chành: + Tần suất BP đó đặt hàng + Có bao nhiêu đơn yêu cầu gấp trước thời gian trả đơn (theo ngày quy định) + Tỷ lệ gấp | F16: 15. BÁO CÁO BỘ PHẬN | J16: Làm theo hướng dẫn trên sheet
A17: 16 | B17: BÁO CÁO CHI PHÍ VẬN CHUYỂN | C17: Chỉ xem | D17: Đánh giá các chỉ số liên quan đến đơn vị vận chuyển | E17: - Từ sheet THU MUA MS QUYÊN, dữ liệu chạy tự động báo cáo gồm các thông tin liên quan đến vận chuyển và giao hàng chành: Ngoài lọc thủ công có dòng tra cứu nhanh trả kết quả + Chi phí Chành + Tần suất Chành + Tỷ lệ chi phí Chành/Đơn hàng + Tỷ lệ tổng chi phí Chành/tổng Đơn hàng | F17: 16. BÁO CÁO CHI PHÍ VẬN CHUYỂN | J17: Làm theo hướng dẫn trên sheet
A19: I. | B19: YÊU CẦU KHÁC
B20: Không đổi tên sheet
B21: Không chèn cột ở giữa, chỉ được thêm cột cuối
B22: Nhân sự tự chịu trách nhiệm nếu sót yêu cầu đến khi triển khai cách thức tiếp nhận đầu vào
B23: Nếu bộ phận yêu cầu cần trả kết quả theo form khác thì phải được duyệt trong Drive này sau đó thu mua chuyển đổi dữ liệu vào form bộ phận yêu cầu
A25: II. | B25: CẤU TRÚC XÂY FOLDER LƯU TRỮ | C25: 5. Nhóm thu mua
B27: CẤP MỤC | C27: FOLDER | D27: HƯỚNG DẪN ĐẶT TÊN | E27: VÍ DỤ
B28: MỤC CẤP 1 | C28: NHÀ CUNG CẤP | D28: STT-Tên viết tắc NCC STT: 2 số | E28: 01- ĐÔNG TÂY
B30: MỤC CẤP 2 | C30: PO | D30: PO-Tên viết tắc NCC | E30: PO-ĐÔNG TÂY
B31: MỤC CẤP 3 | C31: MÃ ĐƠN MUA HÀNG | D31: MÃ ĐƠN MUA HÀNG | E31: DMH0001
B32: FILE LƯU | C32: 1. PHIẾU ĐỀ NGHỊ NHẬP KHO 2. COA, PHIẾU KIỂM CHẤT LƯỢNG 3. ĐƠN MUA HÀNG 4. HÌNH ẢNH HÀNG 5. PHIẾU NHẬP KHO KHO NHẬN 6. PHIẾU XUẤT KHO NCC 7. HỢP ĐỒNG RIÊNG THEO TỪNG PO | D32: DMH0001-TÊN HỒ SƠ | E32: DMH0001-PDN NHẬP KHO
B34: MỤC CẤP 2 | C34: BÁO GIÁ | D34: BÁO GIÁ-Tên viết tắc NCC | E34: BÁO GIÁ-ĐÔNG TÂY
B35: FILE LƯU | C35: CÁC LẦN BÁO GIÁ | D35: BG&STT-dd.mm.yyyy STT: 2 số | E35: BG01-25.03.2026
B38: MỤC CẤP 2 | C38: BB ĐỐI CHIẾU CÔNG NỢ | D38: BB ĐỐI CHIẾU CÔNG NỢ-Tên viết tắc NCC | E38: BB ĐỐI CHIẾU CÔNG NỢ-ĐÔNG TÂY
B39: FILE LƯU | C39: CÁC LẦN ĐỐI CHIẾU CÔNG NỢ | D39: CN&STT-dd.mm.yyyy STT: 2 số | E39: CN01-10.03.2026
B41: MỤC CẤP 2 | C41: HỢP ĐỒNG | D41: HỢP ĐỒNG-Tên viết tắc NCC | E41: HỢP ĐỒNG-ĐÔNG TÂY
B42: FILE LƯU | C42: CÁC LẦN HỢP ĐỒNG NĂM | D42: HĐ&STT-dd.mm.yyyy STT: 2 số | E42: HĐ01-10.03.2026
B44: MỤC CẤP 2 | C44: PHÁP LÝ KHÁC | D44: PHÁP LÝ KHÁC-Tên viết tắc NCC | E44: PHÁP LÝ KHÁC-ĐÔNG TÂY
... B47: MỤC CẤP 1 | C47: SO SÁNH NCC, SẢN PHẨM | D47: MÃ PHIẾU YÊU CẦU-PHÂN LOẠI-TÊN NHÂN VIÊN | E47: PYC.ABA.01.250326-THÙNG-MR. TIÊN

Sheet 1. DATA CHUNG
A1: =IFERROR(__xludf.DUMMYFUNCTION("IMPORTRANGE(""185W47XpkC4eZ2FKSbi1DoXxxlcyxtBBS9e7jlxfUMtE"", ""DATA CHUNG!$A:$AK"")"),"Liên hệ QL update data dữ liệu") -> Liên hệ QL update data dữ liệu | I1: =IFERROR(__xludf.DUMMYFUNCTION("""COMPUTED_VALUE"""),"Phát sinh từ deal với NCC -> thông báo với các bộ phận yêu cầu có liên quan") -> Phát sinh từ deal với NCC -> thông báo với các bộ phận yêu cầu có liên quan | Y1: =IFERROR(__xludf.DUMMYFUNCTION("""COMPUTED_VALUE"""),"Ms Ly bổ sung đầy đủ lại") -> Ms Ly bổ sung đầy đủ lại
A2: =IFERROR(__xludf.DUMMYFUNCTION("""COMPUTED_VALUE"""),"Nếu THương hiệu thì phải có mã KD đầu") -> Nếu THương hiệu thì phải có mã KD đầu | I2: =IFERROR(__xludf.DUMMYFUNCTION("""COMPUTED_VALUE"""),"Danh sách này không được điều chỉnh chỉ được bổ sung thêm") -> Danh sách này không được điều chỉnh chỉ được bổ sung thêm | J2: =IFERROR(__xludf.DUMMYFUNCTION("""COMPUTED_VALUE"""),"Đã bao gồm thủ tục thanh toán nếu phải thanh toán trước Tính từ ngày tiếp nhận yêu cầu đến ngày có hàng ở kho yêu cầu") -> Đã bao gồm thủ tục thanh toán nếu phải thanh toán trước Tính từ ngày tiếp nhận yêu cầu đến ngày có hàng ở kho yêu cầu | L2: =IFERROR(__xludf.DUMMYFUNCTION("""COMPUTED_VALUE"""),"Ngày update quy định mới") -> Ngày update quy định mới | M2: =IFERROR(__xludf.DUMMYFUNCTION("""COMPUTED_VALUE"""),"TRUE: có sẵn FALSE: không có sẵn") -> TRUE: có sẵn FALSE: không có sẵn | T2: =IFERROR(__xludf.DUMMYFUNCTION("""COMPUTED_VALUE"""),"Nhà cung cấp VTBB, NL") -> Nhà cung cấp VTBB, NL | Y2: =IFERROR(__xludf.DUMMYFUNCTION("""COMPUTED_VALUE"""),"NCC gia công nhận VTBB") -> NCC gia công nhận VTBB
A3: =IFERROR(__xludf.DUMMYFUNCTION("""COMPUTED_VALUE"""),"TÊN VIẾT TẮT THƯƠNG HIỆU") -> TÊN VIẾT TẮT THƯƠNG HIỆU | B3: =IFERROR(__xludf.DUMMYFUNCTION("""COMPUTED_VALUE"""),"BP ĐẶT HÀNG/ CÁ NHÂN") -> BP ĐẶT HÀNG/ CÁ NHÂN | D3: =IFERROR(__xludf.DUMMYFUNCTION("""COMPUTED_VALUE"""),"VIẾT TẮT CÔNG TY LẤY HÓA ĐƠN") -> VIẾT TẮT CÔNG TY LẤY HÓA ĐƠN | E3: =IFERROR(__xludf.DUMMYFUNCTION("""COMPUTED_VALUE"""),"TÊN ĐẦY ĐỦ CÔNG TY LẤY HÓA ĐƠN") -> TÊN ĐẦY ĐỦ CÔNG TY LẤY HÓA ĐƠN | F3: =IFERROR(__xludf.DUMMYFUNCTION("""COMPUTED_VALUE"""),"ĐỊA CHỈ CÔNG TY LẤY HÓA ĐƠN") -> ĐỊA CHỈ CÔNG TY LẤY HÓA ĐƠN | G3: =IFERROR(__xludf.DUMMYFUNCTION("""COMPUTED_VALUE"""),"MST CTY LẤY HÓA ĐƠN") -> MST CTY LẤY HÓA ĐƠN | I3: =IFERROR(__xludf.DUMMYFUNCTION("""COMPUTED_VALUE"""),"PHÂN LOẠI VTBB") -> PHÂN LOẠI VTBB | J3: =IFERROR(__xludf.DUMMYFUNCTION("""COMPUTED_VALUE"""),"THỜI GIAN QUY ĐỊNH (Ngày)") -> THỜI GIAN QUY ĐỊNH (Ngày) | K3: =IFERROR(__xludf.DUMMYFUNCTION("""COMPUTED_VALUE"""),"GHI CHÚ") -> GHI CHÚ | L3: =IFERROR(__xludf.DUMMYFUNCTION("""COMPUTED_VALUE"""),"NGÀY ÁP DỤNG") -> NGÀY ÁP DỤNG | M3: =IFERROR(__xludf.DUMMYFUNCTION("""COMPUTED_VALUE"""),"QUY ĐỊNH THEO CÓ SẴN NCC") -> QUY ĐỊNH THEO CÓ SẴN NCC | O3: =IFERROR(__xludf.DUMMYFUNCTION("""COMPUTED_VALUE"""),"ĐVT VTBB/NL") -> ĐVT VTBB/NL | Q3: =IFERROR(__xludf.DUMMYFUNCTION("""COMPUTED_VALUE"""),"TRẠNG THÁI") -> TRẠNG THÁI | R3: =IFERROR(__xludf.DUMMYFUNCTION("""COMPUTED_VALUE"""),"ĐỊNH NGHĨA") -> ĐỊNH NGHĨA | T3: =IFERROR(__xludf.DUMMYFUNCTION("""COMPUTED_VALUE"""),"NCC") -> NCC | U3: =IFERROR(__xludf.DUMMYFUNCTION("""COMPUTED_VALUE"""),"NCC (VIẾT TẮT)") -> NCC (VIẾT TẮT) | V3: =IFERROR(__xludf.DUMMYFUNCTION("""COMPUTED_VALUE"""),"ĐỊA CHỈ NCC") -> ĐỊA CHỈ NCC | W3: =IFERROR(__xludf.DUMMYFUNCTION("""COMPUTED_VALUE"""),"MST NCC") -> MST NCC | Y3: =IFERROR(__xludf.DUMMYFUNCTION("""COMPUTED_VALUE"""),"TÊN PHÁP LÝ KHO NHẬN") -> TÊN PHÁP LÝ KHO NHẬN | Z3: =IFERROR(__xludf.DUMMYFUNCTION("""COMPUTED_VALUE"""),"KHO NHẬN (VIẾT TẮT)") -> KHO NHẬN (VIẾT TẮT) | AA3: =IFERROR(__xludf.DUMMYFUNCTION("""COMPUTED_VALUE"""),"ĐỊA CHỈ KHO NHẬN") -> ĐỊA CHỈ KHO NHẬN | AC3: =IFERROR(__xludf.DUMMYFUNCTION("""COMPUTED_VALUE"""),"ĐƠN VỊ VẬN CHUYỂN") -> ĐƠN VỊ VẬN CHUYỂN | AE3: =IFERROR(__xludf.DUMMYFUNCTION("""COMPUTED_VALUE"""),"ĐVT VC") -> ĐVT VC | AG3: =IFERROR(__xludf.DUMMYFUNCTION("""COMPUTED_VALUE"""),"NSPT") -> NSPT | AI3: =IFERROR(__xludf.DUMMYFUNCTION("""COMPUTED_VALUE"""),"VAT") -> VAT | AK3: =IFERROR(__xludf.DUMMYFUNCTION("""COMPUTED_VALUE"""),"HÌNH THỨC THANH TOÁN CỦA NCC") -> HÌNH THỨC THANH TOÁN CỦA NCC
A4: =IFERROR(__xludf.DUMMYFUNCTION("""COMPUTED_VALUE"""),"NM") -> NM | B4: =IFERROR(__xludf.DUMMYFUNCTION("""COMPUTED_VALUE"""),"Nhà máy Dego") -> Nhà máy Dego | D4: =IFERROR(__xludf.DUMMYFUNCTION("""COMPUTED_VALUE"""),"DEGO HOLDING") -> DEGO HOLDING | E4: =IFERROR(__xludf.DUMMYFUNCTION("""COMPUTED_VALUE"""),"CÔNG TY TNHH DEGO HOLDING") -> CÔNG TY TNHH DEGO HOLDING | F4: =IFERROR(__xludf.DUMMYFUNCTION("""COMPUTED_VALUE"""),"B19 đường dẫn cầu Cần Thơ, QL1A, Khu dân cư Trung tâm văn hóa Tây Đô, Phường Cái Răng, Thành phố Cần Thơ, Việt Nam.") -> B19 đường dẫn cầu Cần Thơ, QL1A, Khu dân cư Trung tâm văn hóa Tây Đô, Phường Cái Răng, Thành phố Cần Thơ, Việt Nam. | G4: =IFERROR(__xludf.DUMMYFUNCTION("""COMPUTED_VALUE"""),"1801722464") -> 1801722464 | I4: =IFERROR(__xludf.DUMMYFUNCTION("""COMPUTED_VALUE"""),"Nhãn") -> Nhãn | J4: =IFERROR(__xludf.DUMMYFUNCTION("""COMPUTED_VALUE"""),7.0) -> 7 | L4: =IFERROR(__xludf.DUMMYFUNCTION("""COMPUTED_VALUE"""),46082.0) -> 46082 | O4: =IFERROR(__xludf.DUMMYFUNCTION("""COMPUTED_VALUE"""),"Cái") -> Cái | Q4: =IFERROR(__xludf.DUMMYFUNCTION("""COMPUTED_VALUE"""),"Chưa đặt hàng") -> Chưa đặt hàng | R4: =IFERROR(__xludf.DUMMYFUNCTION("""COMPUTED_VALUE"""),"Đã tiếp nhận đơn hàng từ BP/người yêu cầu - Chưa gửi đơn hàng cho NCC") -> Đã tiếp nhận đơn hàng từ BP/người yêu cầu - Chưa gửi đơn hàng cho NCC | T4: =IFERROR(__xludf.DUMMYFUNCTION("""COMPUTED_VALUE"""),"CÔNG TY TNHH SẢN XUẤT THƯƠNG MẠI BAO BÌ CẨM HÙNG") -> CÔNG TY TNHH SẢN XUẤT THƯƠNG MẠI BAO BÌ CẨM HÙNG | U4: =IFERROR(__xludf.DUMMYFUNCTION("""COMPUTED_VALUE"""),"Cẩm Hùng") -> Cẩm Hùng | V4: =IFERROR(__xludf.DUMMYFUNCTION("""COMPUTED_VALUE"""),"số 37, đường B11, KDC 91B, Phường Tân An, Thành phố Cần Thơ, Việt Nam") -> số 37, đường B11, KDC 91B, Phường Tân An, Thành phố Cần Thơ, Việt Nam | W4: =IFERROR(__xludf.DUMMYFUNCTION("""COMPUTED_VALUE"""),"1801778241") -> 1801778241 | Y4: =IFERROR(__xludf.DUMMYFUNCTION("""COMPUTED_VALUE"""),"CÔNG TY CỔ PHẦN AGAMA") -> CÔNG TY CỔ PHẦN AGAMA | Z4: =IFERROR(__xludf.DUMMYFUNCTION("""COMPUTED_VALUE"""),"Agama") -> Agama | AA4: =IFERROR(__xludf.DUMMYFUNCTION("""COMPUTED_VALUE"""),"Lô 2, Đường số 2, Cụm Công nghiệp Đức Thuận, Ấp Tràm Lạc, Xã Mỹ Hạnh Bắc, Huyện Đức Hoà, Tỉnh Long An, Việt Nam") -> Lô 2, Đường số 2, Cụm Công nghiệp Đức Thuận, Ấp Tràm Lạc, Xã Mỹ Hạnh Bắc, Huyện Đức Hoà, Tỉnh Long An, Việt Nam | AC4: =IFERROR(__xludf.DUMMYFUNCTION("""COMPUTED_VALUE"""),"Mekong Logistics") -> Mekong Logistics | AE4: =IFERROR(__xludf.DUMMYFUNCTION("""COMPUTED_VALUE"""),"Kiện") -> Kiện | AG4: =IFERROR(__xludf.DUMMYFUNCTION("""COMPUTED_VALUE"""),"Ms Quyên") -> Ms Quyên | AI4: =IFERROR(__xludf.DUMMYFUNCTION("""COMPUTED_VALUE"""),0.05) -> 0.05 | AK4: =IFERROR(__xludf.DUMMYFUNCTION("""COMPUTED_VALUE"""),"Công nợ 60 ngày") -> Công nợ 60 ngày
A5: =IFERROR(__xludf.DUMMYFUNCTION("""COMPUTED_VALUE"""),"SX") -> SX | B5: =IFERROR(__xludf.DUMMYFUNCTION("""COMPUTED_VALUE"""),"SX - Ms Ly") -> SX - Ms Ly | D5: =IFERROR(__xludf.DUMMYFUNCTION("""COMPUTED_VALUE"""),"IDA") -> IDA | E5: =IFERROR(__xludf.DUMMYFUNCTION("""COMPUTED_VALUE"""),"CÔNG TY TNHH XUẤT NHẬP KHẨU IDA GLOBAL") -> CÔNG TY TNHH XUẤT NHẬP KHẨU IDA GLOBAL | F5: =IFERROR(__xludf.DUMMYFUNCTION("""COMPUTED_VALUE"""),"68 Nguyễn Huệ, Phường Sài Gòn, Thành phố Hồ Chí Minh, Việt Nam") -> 68 Nguyễn Huệ, Phường Sài Gòn, Thành phố Hồ Chí Minh, Việt Nam | G5: =IFERROR(__xludf.DUMMYFUNCTION("""COMPUTED_VALUE"""),"0314562909") -> 0314562909 | I5: =IFERROR(__xludf.DUMMYFUNCTION("""COMPUTED_VALUE"""),"Nhãn Metalize") -> Nhãn Metalize | J5: =IFERROR(__xludf.DUMMYFUNCTION("""COMPUTED_VALUE"""),12.0) -> 12 | L5: =IFERROR(__xludf.DUMMYFUNCTION("""COMPUTED_VALUE"""),46082.0) -> 46082 | O5: =IFERROR(__xludf.DUMMYFUNCTION("""COMPUTED_VALUE"""),"Bộ") -> Bộ | Q5: =IFERROR(__xludf.DUMMYFUNCTION("""COMPUTED_VALUE"""),"Đã đặt hàng") -> Đã đặt hàng | R5: =IFERROR(__xludf.DUMMYFUNCTION("""COMPUTED_VALUE"""),"Đã gửi đơn hàng cho NCC") -> Đã gửi đơn hàng cho NCC | T5: =IFERROR(__xludf.DUMMYFUNCTION("""COMPUTED_VALUE"""),"CÔNG TY TNHH SẢN XUẤT BAO BÌ ĐÔNG TÂY") -> CÔNG TY TNHH SẢN XUẤT BAO BÌ ĐÔNG TÂY | U5: =IFERROR(__xludf.DUMMYFUNCTION("""COMPUTED_VALUE"""),"Đông Tây") -> Đông Tây | V5: =IFERROR(__xludf.DUMMYFUNCTION("""COMPUTED_VALUE"""),"0827/3 Đường Võ Thị Thừa, Khu phố 3, Phường An Phú Đông, Quận 12, Thành phố Hồ Chí Minh, Việt Nam") -> 0827/3 Đường Võ Thị Thừa, Khu phố 3, Phường An Phú Đông, Quận 12, Thành phố Hồ Chí Minh, Việt Nam | W5: =IFERROR(__xludf.DUMMYFUNCTION("""COMPUTED_VALUE"""),"0316254811") -> 0316254811 | Y5: =IFERROR(__xludf.DUMMYFUNCTION("""COMPUTED_VALUE"""),"CÔNG TY CỔ PHẦN HÓA CHẤT NÔNG NGHIỆP HÀ LONG") -> CÔNG TY CỔ PHẦN HÓA CHẤT NÔNG NGHIỆP HÀ LONG | Z5: =IFERROR(__xludf.DUMMYFUNCTION("""COMPUTED_VALUE"""),"Hà Long") -> Hà Long | AA5: =IFERROR(__xludf.DUMMYFUNCTION("""COMPUTED_VALUE"""),"Lô A 204, Khu công nghiệp Thái Hòa , Xã Đức Lập Hạ, Huyện Đức Hoà, Tỉnh Long An, Việt Nam") -> Lô A 204, Khu công nghiệp Thái Hòa , Xã Đức Lập Hạ, Huyện Đức Hoà, Tỉnh Long An, Việt Nam | AC5: =IFERROR(__xludf.DUMMYFUNCTION("""COMPUTED_VALUE"""),"Sang Giàu") -> Sang Giàu | AE5: =IFERROR(__xludf.DUMMYFUNCTION("""COMPUTED_VALUE"""),"Chuyến") -> Chuyến | AG5: =IFERROR(__xludf.DUMMYFUNCTION("""COMPUTED_VALUE"""),"Mr Tiên") -> Mr Tiên | AI5: =IFERROR(__xludf.DUMMYFUNCTION("""COMPUTED_VALUE"""),0.08) -> 0.08 | AK5: =IFERROR(__xludf.DUMMYFUNCTION("""COMPUTED_VALUE"""),"Thanh toán 100% khi nhận hàng") -> Thanh toán 100% khi nhận hàng
A6: =IFERROR(__xludf.DUMMYFUNCTION("""COMPUTED_VALUE"""),"LAB") -> LAB | B6: =IFERROR(__xludf.DUMMYFUNCTION("""COMPUTED_VALUE"""),"Lab") -> Lab | D6: =IFERROR(__xludf.DUMMYFUNCTION("""COMPUTED_VALUE"""),"ABA") -> ABA | E6: =IFERROR(__xludf.DUMMYFUNCTION("""COMPUTED_VALUE"""),"CÔNG TY TNHH SẢN XUẤT HÓA CHẤT ABA") -> CÔNG TY TNHH SẢN XUẤT HÓA CHẤT ABA | F6: =IFERROR(__xludf.DUMMYFUNCTION("""COMPUTED_VALUE"""),"108 Trần Đình Xu, Phường Cầu Ông Lãnh, Thành phố Hồ Chí Minh, Việt Nam") -> 108 Trần Đình Xu, Phường Cầu Ông Lãnh, Thành phố Hồ Chí Minh, Việt Nam | G6: =IFERROR(__xludf.DUMMYFUNCTION("""COMPUTED_VALUE"""),"0316342296") -> 0316342296 | I6: =IFERROR(__xludf.DUMMYFUNCTION("""COMPUTED_VALUE"""),"Nhãn Thùng") -> Nhãn Thùng | J6: =IFERROR(__xludf.DUMMYFUNCTION("""COMPUTED_VALUE"""),7.0) -> 7 | L6: =IFERROR(__xludf.DUMMYFUNCTION("""COMPUTED_VALUE"""),46082.0) -> 46082 | O6: =IFERROR(__xludf.DUMMYFUNCTION("""COMPUTED_VALUE"""),"Kg") -> Kg | Q6: =IFERROR(__xludf.DUMMYFUNCTION("""COMPUTED_VALUE"""),"Đã gửi ĐMH cho KT") -> Đã gửi ĐMH cho KT | R6: =IFERROR(__xludf.DUMMYFUNCTION("""COMPUTED_VALUE"""),"Đã gửi bảng giấy ĐMH cho kế toán") -> Đã gửi bảng giấy ĐMH cho kế toán | T6: =IFERROR(__xludf.DUMMYFUNCTION("""COMPUTED_VALUE"""),"CÔNG TY TNHH QUẢNG CÁO MỘC ẤN") -> CÔNG TY TNHH QUẢNG CÁO MỘC ẤN | U6: =IFERROR(__xludf.DUMMYFUNCTION("""COMPUTED_VALUE"""),"Mộc Ấn") -> Mộc Ấn | V6: =IFERROR(__xludf.DUMMYFUNCTION("""COMPUTED_VALUE"""),"368/12 Đường TTH21, Khu phố 3, Phường Tân Thới Hiệp, Quận 12, Thành phố Hồ Chí Minh, Việt Nam") -> 368/12 Đường TTH21, Khu phố 3, Phường Tân Thới Hiệp, Quận 12, Thành phố Hồ Chí Minh, Việt Nam | W6: =IFERROR(__xludf.DUMMYFUNCTION("""COMPUTED_VALUE"""),"0312214688") -> 0312214688 | Y6: =IFERROR(__xludf.DUMMYFUNCTION("""COMPUTED_VALUE"""),"CÔNG TY CỔ PHẦN PHÂN BÓN QUỐC TẾ ÂU VIỆT (CÔNG TY CP EVF)") -> CÔNG TY CỔ PHẦN PHÂN BÓN QUỐC TẾ ÂU VIỆT (CÔNG TY CP EVF) | Z6: =IFERROR(__xludf.DUMMYFUNCTION("""COMPUTED_VALUE"""),"Âu Việt") -> Âu Việt | AA6: =IFERROR(__xludf.DUMMYFUNCTION("""COMPUTED_VALUE"""),"Quốc lộ 1A, Ấp Long An B, Thị Trấn Cái Tắc, Huyện Châu Thành A, Tỉnh Hậu Giang, Việt Nam") -> Quốc lộ 1A, Ấp Long An B, Thị Trấn Cái Tắc, Huyện Châu Thành A, Tỉnh Hậu Giang, Việt Nam | AC6: =IFERROR(__xludf.DUMMYFUNCTION("""COMPUTED_VALUE"""),"Trần Quyên") -> Trần Quyên | AE6: =IFERROR(__xludf.DUMMYFUNCTION("""COMPUTED_VALUE"""),"m²") -> m² | AG6: =IFERROR(__xludf.DUMMYFUNCTION("""COMPUTED_VALUE"""),"Ms Dung") -> Ms Dung | AI6: =IFERROR(__xludf.DUMMYFUNCTION("""COMPUTED_VALUE"""),0.1) -> 0.1 | AK6: =IFERROR(__xludf.DUMMYFUNCTION("""COMPUTED_VALUE"""),"Công nợ 30 ngày") -> Công nợ 30 ngày
A7: =IFERROR(__xludf.DUMMYFUNCTION("""COMPUTED_VALUE"""),"AB") -> AB | B7: =IFERROR(__xludf.DUMMYFUNCTION("""COMPUTED_VALUE"""),"KD ABA") -> KD ABA | D7: =IFERROR(__xludf.DUMMYFUNCTION("""COMPUTED_VALUE"""),"ICARE") -> ICARE | E7: =IFERROR(__xludf.DUMMYFUNCTION("""COMPUTED_VALUE"""),"CÔNG TY TNHH DƯỢC PHẨM ICARE") -> CÔNG TY TNHH DƯỢC PHẨM ICARE | F7: =IFERROR(__xludf.DUMMYFUNCTION("""COMPUTED_VALUE"""),"108 Trần Đình Xu, Phường Cầu Ông Lãnh, Thành phố Hồ Chí Minh, Việt Nam") -> 108 Trần Đình Xu, Phường Cầu Ông Lãnh, Thành phố Hồ Chí Minh, Việt Nam | G7: =IFERROR(__xludf.DUMMYFUNCTION("""COMPUTED_VALUE"""),"0315593265") -> 0315593265 | I7: =IFERROR(__xludf.DUMMYFUNCTION("""COMPUTED_VALUE"""),"Túi flexo") -> Túi flexo | J7: =IFERROR(__xludf.DUMMYFUNCTION("""COMPUTED_VALUE"""),15.0) -> 15 | K7: =IFERROR(__xludf.DUMMYFUNCTION("""COMPUTED_VALUE"""),"Nhãn túi (Tân Đức) <5.000 túi: 12 ngày > 5.000 túi: 15 ngày") -> Nhãn túi (Tân Đức) <5.000 túi: 12 ngày > 5.000 túi: 15 ngày | L7: =IFERROR(__xludf.DUMMYFUNCTION("""COMPUTED_VALUE"""),46023.0) -> 46023 | O7: =IFERROR(__xludf.DUMMYFUNCTION("""COMPUTED_VALUE"""),"Lít") -> Lít | Q7: =IFERROR(__xludf.DUMMYFUNCTION("""COMPUTED_VALUE"""),"Chưa gửi ĐMH cho KT") -> Chưa gửi ĐMH cho KT | R7: =IFERROR(__xludf.DUMMYFUNCTION("""COMPUTED_VALUE"""),"Đã in nhưng chưa đủ chứng từ gửi kế toán") -> Đã in nhưng chưa đủ chứng từ gửi kế toán | T7: =IFERROR(__xludf.DUMMYFUNCTION("""COMPUTED_VALUE"""),"CÔNG TY TNHH SẢN XUẤT- THƯƠNG MẠI- DỊCH VỤ TÂN ĐỨC") -> CÔNG TY TNHH SẢN XUẤT- THƯƠNG MẠI- DỊCH VỤ TÂN ĐỨC | U7: =IFERROR(__xludf.DUMMYFUNCTION("""COMPUTED_VALUE"""),"Tân Đức") -> Tân Đức | V7: =IFERROR(__xludf.DUMMYFUNCTION("""COMPUTED_VALUE"""),"108/8 Đường số 11, Khu phố 5, Phường Linh Xuân, Thành phố Thủ Đức, Thành phố Hồ Chí Minh, Việt Nam") -> 108/8 Đường số 11, Khu phố 5, Phường Linh Xuân, Thành phố Thủ Đức, Thành phố Hồ Chí Minh, Việt Nam | W7: =IFERROR(__xludf.DUMMYFUNCTION("""COMPUTED_VALUE"""),"0301909568") -> 0301909568 | Y7: =IFERROR(__xludf.DUMMYFUNCTION("""COMPUTED_VALUE"""),"CÔNG TY TNHH BASEL THỤY SĨ") -> CÔNG TY TNHH BASEL THỤY SĨ | Z7: =IFERROR(__xludf.DUMMYFUNCTION("""COMPUTED_VALUE"""),"Basel") -> Basel | AA7: =IFERROR(__xludf.DUMMYFUNCTION("""COMPUTED_VALUE"""),"Lô H2A đường số 4, KCN Hải Sơn (GĐ 3+4), ấp Bình Tiền 2, Xã Đức Hòa Hạ, Huyện Đức Hoà, Tỉnh Long An") -> Lô H2A đường số 4, KCN Hải Sơn (GĐ 3+4), ấp Bình Tiền 2, Xã Đức Hòa Hạ, Huyện Đức Hoà, Tỉnh Long An | AC7: =IFERROR(__xludf.DUMMYFUNCTION("""COMPUTED_VALUE"""),"Phan Khánh") -> Phan Khánh | AE7: =IFERROR(__xludf.DUMMYFUNCTION("""COMPUTED_VALUE"""),"Tấn") -> Tấn | AG7: =IFERROR(__xludf.DUMMYFUNCTION("""COMPUTED_VALUE"""),"Mr Hậu") -> Mr Hậu | AI7: =IFERROR(__xludf.DUMMYFUNCTION("""COMPUTED_VALUE"""),0.02) -> 0.02 | AK7: =IFERROR(__xludf.DUMMYFUNCTION("""COMPUTED_VALUE"""),"Thanh toán trước khi giao hàng") -> Thanh toán trước khi giao hàng
A8: =IFERROR(__xludf.DUMMYFUNCTION("""COMPUTED_VALUE"""),"IC") -> IC | B8: =IFERROR(__xludf.DUMMYFUNCTION("""COMPUTED_VALUE"""),"KD ICARE") -> KD ICARE | D8: =IFERROR(__xludf.DUMMYFUNCTION("""COMPUTED_VALUE"""),"NPP DR.XANH") -> NPP DR.XANH | E8: =IFERROR(__xludf.DUMMYFUNCTION("""COMPUTED_VALUE"""),"NHÀ PHÂN PHỐI DR XANH") -> NHÀ PHÂN PHỐI DR XANH | F8: =IFERROR(__xludf.DUMMYFUNCTION("""COMPUTED_VALUE"""),"Số 124, Đường Võ Văn Kiệt, khu vực Bình Trung, Phường Long Hòa, Quận Bình Thủy, TP.Cần Thơ") -> Số 124, Đường Võ Văn Kiệt, khu vực Bình Trung, Phường Long Hòa, Quận Bình Thủy, TP.Cần Thơ | G8: =IFERROR(__xludf.DUMMYFUNCTION("""COMPUTED_VALUE"""),"57B8010406") -> 57B8010406 | I8: =IFERROR(__xludf.DUMMYFUNCTION("""COMPUTED_VALUE"""),"Túi trục") -> Túi trục | J8: =IFERROR(__xludf.DUMMYFUNCTION("""COMPUTED_VALUE"""),21.0) -> 21 | K8: =IFERROR(__xludf.DUMMYFUNCTION("""COMPUTED_VALUE"""),"Làm trục: 12 - 15 ngày In túi: 3 -5 ngày Cắt: 1-2 ngày") -> Làm trục: 12 - 15 ngày In túi: 3 -5 ngày Cắt: 1-2 ngày | L8: =IFERROR(__xludf.DUMMYFUNCTION("""COMPUTED_VALUE"""),46082.0) -> 46082 | O8: =IFERROR(__xludf.DUMMYFUNCTION("""COMPUTED_VALUE"""),"Ml") -> Ml | Q8: =IFERROR(__xludf.DUMMYFUNCTION("""COMPUTED_VALUE"""),"Đã nhận hàng") -> Đã nhận hàng | R8: =IFERROR(__xludf.DUMMYFUNCTION("""COMPUTED_VALUE"""),"Hàng đã về địa chỉ kho yêu cầu") -> Hàng đã về địa chỉ kho yêu cầu | T8: =IFERROR(__xludf.DUMMYFUNCTION("""COMPUTED_VALUE"""),"CÔNG TY TRÁCH NHIỆM HỮU HẠN MỘT THÀNH VIÊN HỢP TRÍ THÀNH CÔNG") -> CÔNG TY TRÁCH NHIỆM HỮU HẠN MỘT THÀNH VIÊN HỢP TRÍ THÀNH CÔNG | U8: =IFERROR(__xludf.DUMMYFUNCTION("""COMPUTED_VALUE"""),"Thành Công") -> Thành Công | V8: =IFERROR(__xludf.DUMMYFUNCTION("""COMPUTED_VALUE"""),"98, đường 3/2, Phường Xuân Khánh, Quận Ninh Kiều, Thành phố Cần Thơ, Việt Nam") -> 98, đường 3/2, Phường Xuân Khánh, Quận Ninh Kiều, Thành phố Cần Thơ, Việt Nam | W8: =IFERROR(__xludf.DUMMYFUNCTION("""COMPUTED_VALUE"""),"1801356017") -> 1801356017 | Y8: =IFERROR(__xludf.DUMMYFUNCTION("""COMPUTED_VALUE"""),"CÔNG TY TNHH DEGO HOLDING") -> CÔNG TY TNHH DEGO HOLDING | Z8: =IFERROR(__xludf.DUMMYFUNCTION("""COMPUTED_VALUE"""),"Dego Cần Thơ") -> Dego Cần Thơ | AA8: =IFERROR(__xludf.DUMMYFUNCTION("""COMPUTED_VALUE"""),"Thửa đất số 86-Tờ bản đồ số 1, đường dẫn cầu Cần Thơ, QL 1A, KDC TTVH Tây Đô, P. Hưng Thạnh, Q. Cái Răng, TP. Cần Thơ (Cách trụ sở công an Quận Cái Răng 100m)") -> Thửa đất số 86-Tờ bản đồ số 1, đường dẫn cầu Cần Thơ, QL 1A, KDC TTVH Tây Đô, P. Hưng Thạnh, Q. Cái Răng, TP. Cần Thơ (Cách trụ sở công an Quận Cái Răng 100m) | AC8: =IFERROR(__xludf.DUMMYFUNCTION("""COMPUTED_VALUE"""),"NCC tự vận chuyển") -> NCC tự vận chuyển | AG8: =IFERROR(__xludf.DUMMYFUNCTION("""COMPUTED_VALUE"""),"Ms Thịnh") -> Ms Thịnh | AK8: =IFERROR(__xludf.DUMMYFUNCTION("""COMPUTED_VALUE"""),"Thanh toán 7 ngày sau khi nhận hàng") -> Thanh toán 7 ngày sau khi nhận hàng
A9: =IFERROR(__xludf.DUMMYFUNCTION("""COMPUTED_VALUE"""),"DR") -> DR | B9: =IFERROR(__xludf.DUMMYFUNCTION("""COMPUTED_VALUE"""),"KD DR XANH") -> KD DR XANH | D9: =IFERROR(__xludf.DUMMYFUNCTION("""COMPUTED_VALUE"""),"HỘ KD DR.XANH") -> HỘ KD DR.XANH | E9: =IFERROR(__xludf.DUMMYFUNCTION("""COMPUTED_VALUE"""),"HỘ KINH DOANH DR XANH") -> HỘ KINH DOANH DR XANH | F9: =IFERROR(__xludf.DUMMYFUNCTION("""COMPUTED_VALUE"""),"Ấp Qui Lân 1, Xã Thạnh Quới, Huyện Vĩnh Thạnh, TP Cần Thơ, Việt Nam") -> Ấp Qui Lân 1, Xã Thạnh Quới, Huyện Vĩnh Thạnh, TP Cần Thơ, Việt Nam | G9: =IFERROR(__xludf.DUMMYFUNCTION("""COMPUTED_VALUE"""),"57H8005750") -> 57H8005750 | I9: =IFERROR(__xludf.DUMMYFUNCTION("""COMPUTED_VALUE"""),"Hộp") -> Hộp | J9: =IFERROR(__xludf.DUMMYFUNCTION("""COMPUTED_VALUE"""),15.0) -> 15 | L9: =IFERROR(__xludf.DUMMYFUNCTION("""COMPUTED_VALUE"""),46082.0) -> 46082 | O9: =IFERROR(__xludf.DUMMYFUNCTION("""COMPUTED_VALUE"""),"Gram") -> Gram | Q9: =IFERROR(__xludf.DUMMYFUNCTION("""COMPUTED_VALUE"""),"Hoàn thành") -> Hoàn thành | R9: =IFERROR(__xludf.DUMMYFUNCTION("""COMPUTED_VALUE"""),"Hoàn thành đã lấy hóa đơn; thanh toán; quyết toán hoàn ứng") -> Hoàn thành đã lấy hóa đơn; thanh toán; quyết toán hoàn ứng | T9: =IFERROR(__xludf.DUMMYFUNCTION("""COMPUTED_VALUE"""),"CÔNG TY TNHH SẢN XUẤT - THƯƠNG MẠI AN TÍN") -> CÔNG TY TNHH SẢN XUẤT - THƯƠNG MẠI AN TÍN | U9: =IFERROR(__xludf.DUMMYFUNCTION("""COMPUTED_VALUE"""),"An Tín") -> An Tín | V9: =IFERROR(__xludf.DUMMYFUNCTION("""COMPUTED_VALUE"""),"247/16 Đường Bình Tiên, Phường 08, Quận 6, Thành Phố Hồ Chí Minh, Việt Nam") -> 247/16 Đường Bình Tiên, Phường 08, Quận 6, Thành Phố Hồ Chí Minh, Việt Nam | W9: =IFERROR(__xludf.DUMMYFUNCTION("""COMPUTED_VALUE"""),"0315259038") -> 0315259038 | Y9: =IFERROR(__xludf.DUMMYFUNCTION("""COMPUTED_VALUE"""),"CÔNG TY TNHH PHÂN BÓN NIỀM TIN VIỆT") -> CÔNG TY TNHH PHÂN BÓN NIỀM TIN VIỆT | Z9: =IFERROR(__xludf.DUMMYFUNCTION("""COMPUTED_VALUE"""),"Niềm Tin Việt") -> Niềm Tin Việt | AA9: =IFERROR(__xludf.DUMMYFUNCTION("""COMPUTED_VALUE"""),"Ấp 2A, Xã Hưng Thạnh, H.Tháp Mười, Đồng Tháp") -> Ấp 2A, Xã Hưng Thạnh, H.Tháp Mười, Đồng Tháp | AC9: =IFERROR(__xludf.DUMMYFUNCTION("""COMPUTED_VALUE"""),"Grab") -> Grab | AG9: =IFERROR(__xludf.DUMMYFUNCTION("""COMPUTED_VALUE"""),"Ms Dư") -> Ms Dư | AK9: =IFERROR(__xludf.DUMMYFUNCTION("""COMPUTED_VALUE"""),"Công nợ 20 ngày") -> Công nợ 20 ngày
A10: =IFERROR(__xludf.DUMMYFUNCTION("""COMPUTED_VALUE"""),"ID") -> ID | B10: =IFERROR(__xludf.DUMMYFUNCTION("""COMPUTED_VALUE"""),"KD IDA") -> KD IDA | D10: =IFERROR(__xludf.DUMMYFUNCTION("""COMPUTED_VALUE"""),"BAMBOO") -> BAMBOO | E10: =IFERROR(__xludf.DUMMYFUNCTION("""COMPUTED_VALUE"""),"CÔNG TY TNHH XUẤT NHẬP KHẨU SẢN XUẤT THƯƠNG MẠI BAMBOO VIỆT NAM") -> CÔNG TY TNHH XUẤT NHẬP KHẨU SẢN XUẤT THƯƠNG MẠI BAMBOO VIỆT NAM | F10: =IFERROR(__xludf.DUMMYFUNCTION("""COMPUTED_VALUE"""),"Tầng 18, Tòa nhà ROX Tower, 180-192 Nguyễn Công Trứ, Phường Bến Thành, Thành phó Hồ Chí Minh, Việt Nam.") -> Tầng 18, Tòa nhà ROX Tower, 180-192 Nguyễn Công Trứ, Phường Bến Thành, Thành phó Hồ Chí Minh, Việt Nam. | G10: =IFERROR(__xludf.DUMMYFUNCTION("""COMPUTED_VALUE"""),"0318629897") -> 0318629897 | I10: =IFERROR(__xludf.DUMMYFUNCTION("""COMPUTED_VALUE"""),"Can/Xô") -> Can/Xô | J10: =IFERROR(__xludf.DUMMYFUNCTION("""COMPUTED_VALUE"""),5.0) -> 5 | K10: =IFERROR(__xludf.DUMMYFUNCTION("""COMPUTED_VALUE"""),"Thông tin tham khảo từ Ms Ly/ Thu mua check lại") -> Thông tin tham khảo từ Ms Ly/ Thu mua check lại | L10: =IFERROR(__xludf.DUMMYFUNCTION("""COMPUTED_VALUE"""),46082.0) -> 46082 | M10: =IFERROR(__xludf.DUMMYFUNCTION("""COMPUTED_VALUE"""),TRUE) -> TRUE | O10: =IFERROR(__xludf.DUMMYFUNCTION("""COMPUTED_VALUE"""),"Cuộn") -> Cuộn | Q10: =IFERROR(__xludf.DUMMYFUNCTION("""COMPUTED_VALUE"""),"Hủy đơn") -> Hủy đơn | R10: =IFERROR(__xludf.DUMMYFUNCTION("""COMPUTED_VALUE"""),"Hủy đơn với NCC theo bộ phận yêu cầu") -> Hủy đơn với NCC theo bộ phận yêu cầu | T10: =IFERROR(__xludf.DUMMYFUNCTION("""COMPUTED_VALUE"""),"CÔNG TY TNHH SẢN XUẤT THƯƠNG MẠI NHỰA CƯỜNG PHÁT LONG AN") -> CÔNG TY TNHH SẢN XUẤT THƯƠNG MẠI NHỰA CƯỜNG PHÁT LONG AN | U10: =IFERROR(__xludf.DUMMYFUNCTION("""COMPUTED_VALUE"""),"Cường Phát") -> Cường Phát | V10: =IFERROR(__xludf.DUMMYFUNCTION("""COMPUTED_VALUE"""),"Ấp Hóc Thơm 1, Xã Hòa Khánh, Tỉnh Tây Ninh, Việt Nam") -> Ấp Hóc Thơm 1, Xã Hòa Khánh, Tỉnh Tây Ninh, Việt Nam | W10: =IFERROR(__xludf.DUMMYFUNCTION("""COMPUTED_VALUE"""),"1101721810") -> 1101721810 | Y10: =IFERROR(__xludf.DUMMYFUNCTION("""COMPUTED_VALUE"""),"CÔNG TY TNHH PRIMA - PHÁP - CHÂU ÂU") -> CÔNG TY TNHH PRIMA - PHÁP - CHÂU ÂU | Z10: =IFERROR(__xludf.DUMMYFUNCTION("""COMPUTED_VALUE"""),"Đại Tâm") -> Đại Tâm | AA10: =IFERROR(__xludf.DUMMYFUNCTION("""COMPUTED_VALUE"""),"Lô B101 đường B. KCN Thái Hoà, Xã Đức Lập Hạ, Huyện Đức Hoà, Tỉnh Long An") -> Lô B101 đường B. KCN Thái Hoà, Xã Đức Lập Hạ, Huyện Đức Hoà, Tỉnh Long An
A11: =IFERROR(__xludf.DUMMYFUNCTION("""COMPUTED_VALUE"""),"SX") -> SX | B11: =IFERROR(__xludf.DUMMYFUNCTION("""COMPUTED_VALUE"""),"SX - Ms Hương") -> SX - Ms Hương | D11: =IFERROR(__xludf.DUMMYFUNCTION("""COMPUTED_VALUE"""),"N2SBIO") -> N2SBIO | E11: =IFERROR(__xludf.DUMMYFUNCTION("""COMPUTED_VALUE"""),"CÔNG TY TNHH N2SBIO VIỆT NAM") -> CÔNG TY TNHH N2SBIO VIỆT NAM | F11: =IFERROR(__xludf.DUMMYFUNCTION("""COMPUTED_VALUE"""),"108 Trần Đình Xu, Phường Nguyễn Cư Trinh, Quận 1, TP Hồ Chí Minh") -> 108 Trần Đình Xu, Phường Nguyễn Cư Trinh, Quận 1, TP Hồ Chí Minh | G11: =IFERROR(__xludf.DUMMYFUNCTION("""COMPUTED_VALUE"""),"0318776965") -> 0318776965 | I11: =IFERROR(__xludf.DUMMYFUNCTION("""COMPUTED_VALUE"""),"Can/Xô") -> Can/Xô | J11: =IFERROR(__xludf.DUMMYFUNCTION("""COMPUTED_VALUE"""),7.0) -> 7 | K11: =IFERROR(__xludf.DUMMYFUNCTION("""COMPUTED_VALUE"""),"Thông tin tham khảo từ Ms Ly/ Thu mua check lại") -> Thông tin tham khảo từ Ms Ly/ Thu mua check lại | L11: =IFERROR(__xludf.DUMMYFUNCTION("""COMPUTED_VALUE"""),46082.0) -> 46082 | M11: =IFERROR(__xludf.DUMMYFUNCTION("""COMPUTED_VALUE"""),FALSE) -> FALSE | O11: =IFERROR(__xludf.DUMMYFUNCTION("""COMPUTED_VALUE"""),"Bịch") -> Bịch | Q11: =IFERROR(__xludf.DUMMYFUNCTION("""COMPUTED_VALUE"""),"Tạm ngưng") -> Tạm ngưng | T11: =IFERROR(__xludf.DUMMYFUNCTION("""COMPUTED_VALUE"""),"CÔNG TY TNHH BAO BÌ HNS") -> CÔNG TY TNHH BAO BÌ HNS | U11: =IFERROR(__xludf.DUMMYFUNCTION("""COMPUTED_VALUE"""),"Hns") -> Hns | V11: =IFERROR(__xludf.DUMMYFUNCTION("""COMPUTED_VALUE"""),"084 QL1, KV2, Ba Láng, Cái Răng, Cần Thơ") -> 084 QL1, KV2, Ba Láng, Cái Răng, Cần Thơ | W11: =IFERROR(__xludf.DUMMYFUNCTION("""COMPUTED_VALUE"""),"1801399719") -> 1801399719 | Y11: =IFERROR(__xludf.DUMMYFUNCTION("""COMPUTED_VALUE"""),"CÔNG TY TNHH SÀN GIAO DỊCH THUỐC BẢO VỆ THỰC VẬT VIỆT NAM") -> CÔNG TY TNHH SÀN GIAO DỊCH THUỐC BẢO VỆ THỰC VẬT VIỆT NAM | Z11: =IFERROR(__xludf.DUMMYFUNCTION("""COMPUTED_VALUE"""),"Pesticidex") -> Pesticidex | AA11: =IFERROR(__xludf.DUMMYFUNCTION("""COMPUTED_VALUE"""),"Tầng 1, B19 đường dẫn cầu Cần Thơ, Quốc lộ 1A, KDC TTVH Tây Đô, Phường Hưng Thạnh, Quận Cái Răng, Thành phố Cần Thơ, Việt Nam") -> Tầng 1, B19 đường dẫn cầu Cần Thơ, Quốc lộ 1A, KDC TTVH Tây Đô, Phường Hưng Thạnh, Quận Cái Răng, Thành phố Cần Thơ, Việt Nam
A12: =IFERROR(__xludf.DUMMYFUNCTION("""COMPUTED_VALUE"""),"TM") -> TM | B12: =IFERROR(__xludf.DUMMYFUNCTION("""COMPUTED_VALUE"""),"TM - Ms Quyên") -> TM - Ms Quyên | D12: =IFERROR(__xludf.DUMMYFUNCTION("""COMPUTED_VALUE"""),"NN DEGO") -> NN DEGO | E12: =IFERROR(__xludf.DUMMYFUNCTION("""COMPUTED_VALUE"""),"CÔNG TY TNHH SẢN XUẤT VÀ XUẤT NHẬP KHẨU HOÁ CHẤT NÔNG NGHIỆP DEGO") -> CÔNG TY TNHH SẢN XUẤT VÀ XUẤT NHẬP KHẨU HOÁ CHẤT NÔNG NGHIỆP DEGO | F12: =IFERROR(__xludf.DUMMYFUNCTION("""COMPUTED_VALUE"""),"Tầng 9, tòa nhà K&M Tower, 33 Ung Văn Khiêm, Phường Thạnh Mỹ Tây, TP Hồ Chí Minh, Việt Nam") -> Tầng 9, tòa nhà K&M Tower, 33 Ung Văn Khiêm, Phường Thạnh Mỹ Tây, TP Hồ Chí Minh, Việt Nam | G12: =IFERROR(__xludf.DUMMYFUNCTION("""COMPUTED_VALUE"""),"0318430011") -> 0318430011 | I12: =IFERROR(__xludf.DUMMYFUNCTION("""COMPUTED_VALUE"""),"NL") -> NL | J12: =IFERROR(__xludf.DUMMYFUNCTION("""COMPUTED_VALUE"""),10.0) -> 10 | K12: =IFERROR(__xludf.DUMMYFUNCTION("""COMPUTED_VALUE"""),"Trong nước") -> Trong nước | L12: =IFERROR(__xludf.DUMMYFUNCTION("""COMPUTED_VALUE"""),46082.0) -> 46082 | M12: =IFERROR(__xludf.DUMMYFUNCTION("""COMPUTED_VALUE"""),TRUE) -> TRUE | O12: =IFERROR(__xludf.DUMMYFUNCTION("""COMPUTED_VALUE"""),"Cây") -> Cây | T12: =IFERROR(__xludf.DUMMYFUNCTION("""COMPUTED_VALUE"""),"CÔNG TY TNHH MTV SẢN XUẤT THƯƠNG MẠI NHỰA HỒ GIA") -> CÔNG TY TNHH MTV SẢN XUẤT THƯƠNG MẠI NHỰA HỒ GIA | U12: =IFERROR(__xludf.DUMMYFUNCTION("""COMPUTED_VALUE"""),"Hồ Gia") -> Hồ Gia | V12: =IFERROR(__xludf.DUMMYFUNCTION("""COMPUTED_VALUE"""),"100/7B khu phố 1, Bùi Dương Lịch, Phường Bình Hưng Hòa B, Quận Bình Tân, Thành phố Hồ Chí Minh") -> 100/7B khu phố 1, Bùi Dương Lịch, Phường Bình Hưng Hòa B, Quận Bình Tân, Thành phố Hồ Chí Minh | W12: =IFERROR(__xludf.DUMMYFUNCTION("""COMPUTED_VALUE"""),"0315743256") -> 0315743256 | Y12: =IFERROR(__xludf.DUMMYFUNCTION("""COMPUTED_VALUE"""),"CÔNG TY TNHH SX TM YAMATO VN") -> CÔNG TY TNHH SX TM YAMATO VN | Z12: =IFERROR(__xludf.DUMMYFUNCTION("""COMPUTED_VALUE"""),"Yamato") -> Yamato | AA12: =IFERROR(__xludf.DUMMYFUNCTION("""COMPUTED_VALUE"""),"Lô A20A Đường số 6, KCN Hải Sơn (GĐ 3+4), Xã Đức Hòa Hạ, Huyện Đức Hoà, Tỉnh Long An") -> Lô A20A Đường số 6, KCN Hải Sơn (GĐ 3+4), Xã Đức Hòa Hạ, Huyện Đức Hoà, Tỉnh Long An
A13: =IFERROR(__xludf.DUMMYFUNCTION("""COMPUTED_VALUE"""),"N2") -> N2 | B13: =IFERROR(__xludf.DUMMYFUNCTION("""COMPUTED_VALUE"""),"KD N2SBIO") -> KD N2SBIO | D13: =IFERROR(__xludf.DUMMYFUNCTION("""COMPUTED_VALUE"""),"NN ABA") -> NN ABA | E13: =IFERROR(__xludf.DUMMYFUNCTION("""COMPUTED_VALUE"""),"CÔNG TY TNHH HÓA CHẤT NÔNG NGHIỆP ABA") -> CÔNG TY TNHH HÓA CHẤT NÔNG NGHIỆP ABA | F13: =IFERROR(__xludf.DUMMYFUNCTION("""COMPUTED_VALUE"""),"B18 đường dẫn cầu Cần Thơ, QL1A, Khu dân cư Trung tâm văn hóa Tây Đô, Phường Cái Răng, Thành phố Cần Thơ, Việt Nam.") -> B18 đường dẫn cầu Cần Thơ, QL1A, Khu dân cư Trung tâm văn hóa Tây Đô, Phường Cái Răng, Thành phố Cần Thơ, Việt Nam. | G13: =IFERROR(__xludf.DUMMYFUNCTION("""COMPUTED_VALUE"""),"1801818328") -> 1801818328 | I13: =IFERROR(__xludf.DUMMYFUNCTION("""COMPUTED_VALUE"""),"NL") -> NL | J13: =IFERROR(__xludf.DUMMYFUNCTION("""COMPUTED_VALUE"""),14.0) -> 14 | K13: =IFERROR(__xludf.DUMMYFUNCTION("""COMPUTED_VALUE"""),"Trong nước") -> Trong nước | L13: =IFERROR(__xludf.DUMMYFUNCTION("""COMPUTED_VALUE"""),46082.0) -> 46082 | M13: =IFERROR(__xludf.DUMMYFUNCTION("""COMPUTED_VALUE"""),FALSE) -> FALSE | O13: =IFERROR(__xludf.DUMMYFUNCTION("""COMPUTED_VALUE"""),"Thùng") -> Thùng | T13: =IFERROR(__xludf.DUMMYFUNCTION("""COMPUTED_VALUE"""),"CÔNG TY TNHH BAO BÌ MINH NGỌC") -> CÔNG TY TNHH BAO BÌ MINH NGỌC | U13: =IFERROR(__xludf.DUMMYFUNCTION("""COMPUTED_VALUE"""),"Minh Ngọc") -> Minh Ngọc | V13: =IFERROR(__xludf.DUMMYFUNCTION("""COMPUTED_VALUE"""),"Lô D2.1 - D2.2 Đường số 4, KCN Nhị Xuân, Xã Xuân Thới Sơn, Huyện Hóc Môn, Tp. HCM") -> Lô D2.1 - D2.2 Đường số 4, KCN Nhị Xuân, Xã Xuân Thới Sơn, Huyện Hóc Môn, Tp. HCM | W13: =IFERROR(__xludf.DUMMYFUNCTION("""COMPUTED_VALUE"""),"0313694927") -> 0313694927 | Y13: =IFERROR(__xludf.DUMMYFUNCTION("""COMPUTED_VALUE"""),"CÔNG TY TNHH XUẤT NHẬP KHẨU HÓA CHẤT ATC") -> CÔNG TY TNHH XUẤT NHẬP KHẨU HÓA CHẤT ATC | Z13: =IFERROR(__xludf.DUMMYFUNCTION("""COMPUTED_VALUE"""),"ATC") -> ATC | AA13: =IFERROR(__xludf.DUMMYFUNCTION("""COMPUTED_VALUE"""),"Số 87, Đường Lý Bôn, Phường Bình Đức, Tỉnh An Giang, Việt Nam") -> Số 87, Đường Lý Bôn, Phường Bình Đức, Tỉnh An Giang, Việt Nam
A14: =IFERROR(__xludf.DUMMYFUNCTION("""COMPUTED_VALUE"""),"QLTM_MS NGÂN") -> QLTM_MS NGÂN | B14: =IFERROR(__xludf.DUMMYFUNCTION("""COMPUTED_VALUE"""),"QLTM_Ms Ngân") -> QLTM_Ms Ngân | I14: =IFERROR(__xludf.DUMMYFUNCTION("""COMPUTED_VALUE"""),"Thùng") -> Thùng | J14: =IFERROR(__xludf.DUMMYFUNCTION("""COMPUTED_VALUE"""),18.0) -> 18 | K14: =IFERROR(__xludf.DUMMYFUNCTION("""COMPUTED_VALUE"""),"Thời gian Sx: 15 ngày Nhận hàng: 2 ngày") -> Thời gian Sx: 15 ngày Nhận hàng: 2 ngày | L14: =IFERROR(__xludf.DUMMYFUNCTION("""COMPUTED_VALUE"""),46082.0) -> 46082 | O14: =IFERROR(__xludf.DUMMYFUNCTION("""COMPUTED_VALUE"""),"Hộp") -> Hộp | T14: =IFERROR(__xludf.DUMMYFUNCTION("""COMPUTED_VALUE"""),"CÔNG TY TNHH SX TM DV QUỐC TẾ QUANG ĐẠT") -> CÔNG TY TNHH SX TM DV QUỐC TẾ QUANG ĐẠT | U14: =IFERROR(__xludf.DUMMYFUNCTION("""COMPUTED_VALUE"""),"Quang Đạt") -> Quang Đạt | V14: =IFERROR(__xludf.DUMMYFUNCTION("""COMPUTED_VALUE"""),"43D, Ao Đôi, P. Bình Trị Đông A, Q. Bình Tân, TP. HCM") -> 43D, Ao Đôi, P. Bình Trị Đông A, Q. Bình Tân, TP. HCM | W14: =IFERROR(__xludf.DUMMYFUNCTION("""COMPUTED_VALUE"""),"0317703989") -> 0317703989 | Y14: =IFERROR(__xludf.DUMMYFUNCTION("""COMPUTED_VALUE"""),"CÔNG TY TNHH AGRIFUTURE") -> CÔNG TY TNHH AGRIFUTURE | Z14: =IFERROR(__xludf.DUMMYFUNCTION("""COMPUTED_VALUE"""),"Agrifuture") -> Agrifuture | AA14: =IFERROR(__xludf.DUMMYFUNCTION("""COMPUTED_VALUE"""),"Nhà Máy: Lô B123B, Đường số 7, KCN, ấp Tân Hòa, Đức Hòa, Long An VP: Phòng A4.04, Khu Phức Hợp Căn Hộ Nhật Hoa, 33 Nguyễn Hữu Thọ, Phường Tân Hưng, Thành phố Hồ Chí Minh, Việt Nam") -> Nhà Máy: Lô B123B, Đường số 7, KCN, ấp Tân Hòa, Đức Hòa, Long An VP: Phòng A4.04, Khu Phức Hợp Căn Hộ Nhật Hoa, 33 Nguyễn Hữu Thọ, Phường Tân Hưng, Thành phố Hồ Chí Minh, Việt Nam
I15: =IFERROR(__xludf.DUMMYFUNCTION("""COMPUTED_VALUE"""),"Chai Nhôm") -> Chai Nhôm | J15: =IFERROR(__xludf.DUMMYFUNCTION("""COMPUTED_VALUE"""),8.0) -> 8 | K15: =IFERROR(__xludf.DUMMYFUNCTION("""COMPUTED_VALUE"""),"Hàng cần thanh toán trước: - Làm hồ sơ 1 ngày - Thanh toán 5 ngày - Nhận hàng 2 ngày (Thông tin tham khảo từ Ms Ly/ Thu mua check lại)") -> Hàng cần thanh toán trước: - Làm hồ sơ 1 ngày - Thanh toán 5 ngày - Nhận hàng 2 ngày (Thông tin tham khảo từ Ms Ly/ Thu mua check lại) | L15: =IFERROR(__xludf.DUMMYFUNCTION("""COMPUTED_VALUE"""),46082.0) -> 46082 | M15: =IFERROR(__xludf.DUMMYFUNCTION("""COMPUTED_VALUE"""),TRUE) -> TRUE | T15: =IFERROR(__xludf.DUMMYFUNCTION("""COMPUTED_VALUE"""),"CÔNG TY CỔ PHẦN BAO BÌ NHỰA THÀNH PHÁT") -> CÔNG TY CỔ PHẦN BAO BÌ NHỰA THÀNH PHÁT | U15: =IFERROR(__xludf.DUMMYFUNCTION("""COMPUTED_VALUE"""),"Thành Phát") -> Thành Phát | V15: =IFERROR(__xludf.DUMMYFUNCTION("""COMPUTED_VALUE"""),"F01-1, đường số 1, KCN Hạnh Phúc, ấp 5 Đức Hoà Đông, ĐH, LA") -> F01-1, đường số 1, KCN Hạnh Phúc, ấp 5 Đức Hoà Đông, ĐH, LA | W15: =IFERROR(__xludf.DUMMYFUNCTION("""COMPUTED_VALUE"""),"0302299160") -> 0302299160 | Y15: =IFERROR(__xludf.DUMMYFUNCTION("""COMPUTED_VALUE"""),"Cty TNHH SX TM DV Thu Loan") -> Cty TNHH SX TM DV Thu Loan | Z15: =IFERROR(__xludf.DUMMYFUNCTION("""COMPUTED_VALUE"""),"Thu Loan") -> Thu Loan | AA15: =IFERROR(__xludf.DUMMYFUNCTION("""COMPUTED_VALUE"""),"699 tổ 34 Khóm Đông Thuận , Phường Đông Thành , Bình Minh, Vĩnh Long") -> 699 tổ 34 Khóm Đông Thuận , Phường Đông Thành , Bình Minh, Vĩnh Long
I16: =IFERROR(__xludf.DUMMYFUNCTION("""COMPUTED_VALUE"""),"Chai Nhôm") -> Chai Nhôm | J16: =IFERROR(__xludf.DUMMYFUNCTION("""COMPUTED_VALUE"""),33.0) -> 33 | K16: =IFERROR(__xludf.DUMMYFUNCTION("""COMPUTED_VALUE"""),"Hàng cần thanh toán trước: - Làm hồ sơ 1 ngày - Nhập khẩu : 25 ngày - Thanh toán 5 ngày - Nhận hàng 2 ngày (Thông tin tham khảo từ Ms Ly/ Thu mua check lại)") -> Hàng cần thanh toán trước: - Làm hồ sơ 1 ngày - Nhập khẩu : 25 ngày - Thanh toán 5 ngày - Nhận hàng 2 ngày (Thông tin tham khảo từ Ms Ly/ Thu mua check lại) | L16: =IFERROR(__xludf.DUMMYFUNCTION("""COMPUTED_VALUE"""),46082.0) -> 46082 | M16: =IFERROR(__xludf.DUMMYFUNCTION("""COMPUTED_VALUE"""),FALSE) -> FALSE | T16: =IFERROR(__xludf.DUMMYFUNCTION("""COMPUTED_VALUE"""),"CÔNG TY TNHH BAO BÌ NHỰA PHƯƠNG NAM") -> CÔNG TY TNHH BAO BÌ NHỰA PHƯƠNG NAM | U16: =IFERROR(__xludf.DUMMYFUNCTION("""COMPUTED_VALUE"""),"Phương Nam") -> Phương Nam | V16: =IFERROR(__xludf.DUMMYFUNCTION("""COMPUTED_VALUE"""),"384A, Tổ 3, Ấp 1, Xã Mỹ Hạnh, Tỉnh Tây Ninh, Việt Nam") -> 384A, Tổ 3, Ấp 1, Xã Mỹ Hạnh, Tỉnh Tây Ninh, Việt Nam | W16: =IFERROR(__xludf.DUMMYFUNCTION("""COMPUTED_VALUE"""),"0301515210") -> 0301515210 | Y16: =IFERROR(__xludf.DUMMYFUNCTION("""COMPUTED_VALUE"""),"CÔNG TY TNHH THƯƠNG MẠI THÁI NÔNG") -> CÔNG TY TNHH THƯƠNG MẠI THÁI NÔNG | Z16: =IFERROR(__xludf.DUMMYFUNCTION("""COMPUTED_VALUE"""),"Thái Nông") -> Thái Nông | AA16: =IFERROR(__xludf.DUMMYFUNCTION("""COMPUTED_VALUE"""),"73 Lạc Long Quân, Phường 1, Quận 11, Thành phố Hồ Chí Minh CN: Khu Công nghiệp Nhơn Trạch 3, Thị trấn Hiệp Phước, Huyện Nhơn Trạch, Tỉnh Đồng Nai, Việt Nam Giao Vật Tư: HKD Cơ Sở Phân Bón Lá Phú Hưng ĐC: 49A, đường số 27, Tân Lập, Tân Thông Hội, Củ Chi, H"&"CM Người nhận: 0937 021 818 - Chị Bội") -> 73 Lạc Long Quân, Phường 1, Quận 11, Thành phố Hồ Chí Minh CN: Khu Công nghiệp Nhơn Trạch 3, Thị trấn Hiệp Phước, Huyện Nhơn Trạch, Tỉnh Đồng Nai, Việt Nam Giao Vật Tư: HKD Cơ Sở Phân Bón Lá Phú Hưng ĐC: 49A, đường số 27, Tân Lập, Tân Thông Hội, Củ Chi, HCM Người nhận: 0937 021 818 - Chị Bội
I17: =IFERROR(__xludf.DUMMYFUNCTION("""COMPUTED_VALUE"""),"Chai khác") -> Chai khác | J17: =IFERROR(__xludf.DUMMYFUNCTION("""COMPUTED_VALUE"""),7.0) -> 7 | K17: =IFERROR(__xludf.DUMMYFUNCTION("""COMPUTED_VALUE"""),"Hàng cần thanh toán trước: - Làm hồ sơ 1 ngày - Thanh toán 5 ngày - Sản xuất 0 ngày - Nhận hàng 2 ngày") -> Hàng cần thanh toán trước: - Làm hồ sơ 1 ngày - Thanh toán 5 ngày - Sản xuất 0 ngày - Nhận hàng 2 ngày | L17: =IFERROR(__xludf.DUMMYFUNCTION("""COMPUTED_VALUE"""),46082.0) -> 46082 | M17: =IFERROR(__xludf.DUMMYFUNCTION("""COMPUTED_VALUE"""),TRUE) -> TRUE | T17: =IFERROR(__xludf.DUMMYFUNCTION("""COMPUTED_VALUE"""),"CÔNG TY CỔ PHẦN PHL") -> CÔNG TY CỔ PHẦN PHL | U17: =IFERROR(__xludf.DUMMYFUNCTION("""COMPUTED_VALUE"""),"PHL") -> PHL | V17: =IFERROR(__xludf.DUMMYFUNCTION("""COMPUTED_VALUE"""),"Lô MB1-1, Lô MB1-1a, khu công nghiệp Đức Hòa 1, Đường số 5, Ấp 5, Xã Đức Hòa Đông, Huyện Đức Hoà, Tỉnh Long An, Việt Nam") -> Lô MB1-1, Lô MB1-1a, khu công nghiệp Đức Hòa 1, Đường số 5, Ấp 5, Xã Đức Hòa Đông, Huyện Đức Hoà, Tỉnh Long An, Việt Nam | W17: =IFERROR(__xludf.DUMMYFUNCTION("""COMPUTED_VALUE"""),"1101392309") -> 1101392309 | Y17: =IFERROR(__xludf.DUMMYFUNCTION("""COMPUTED_VALUE"""),"CÔNG TY TNHH TẬP ĐOÀN AN NÔNG (AN GROUP)") -> CÔNG TY TNHH TẬP ĐOÀN AN NÔNG (AN GROUP) | Z17: =IFERROR(__xludf.DUMMYFUNCTION("""COMPUTED_VALUE"""),"An Nông") -> An Nông | AA17: =IFERROR(__xludf.DUMMYFUNCTION("""COMPUTED_VALUE"""),"Trụ sở : 464 Đường số 7, khu phố 8, Phường Tân Tạo, Quận Bình Tân, TP Hồ Chí Minh Nhà máy : Lô H7, Đường số 5, KCN Hải Sơn (GĐ 3+4), ấp Bình Tiền 2, Xã Đức Hòa Hạ, Huyện Đức Hoà, Tỉnh Long An, Việt Nam") -> Trụ sở : 464 Đường số 7, khu phố 8, Phường Tân Tạo, Quận Bình Tân, TP Hồ Chí Minh Nhà máy : Lô H7, Đường số 5, KCN Hải Sơn (GĐ 3+4), ấp Bình Tiền 2, Xã Đức Hòa Hạ, Huyện Đức Hoà, Tỉnh Long An, Việt Nam
I18: =IFERROR(__xludf.DUMMYFUNCTION("""COMPUTED_VALUE"""),"Nắp") -> Nắp | J18: =IFERROR(__xludf.DUMMYFUNCTION("""COMPUTED_VALUE"""),7.0) -> 7 | K18: =IFERROR(__xludf.DUMMYFUNCTION("""COMPUTED_VALUE"""),"Nắp NCC giao chung hàng với chai.") -> Nắp NCC giao chung hàng với chai. | L18: =IFERROR(__xludf.DUMMYFUNCTION("""COMPUTED_VALUE"""),46082.0) -> 46082 | M18: =IFERROR(__xludf.DUMMYFUNCTION("""COMPUTED_VALUE"""),TRUE) -> TRUE | T18: =IFERROR(__xludf.DUMMYFUNCTION("""COMPUTED_VALUE"""),"CÔNG TY TNHH SẢN XUẤT BAO BÌ VINACO") -> CÔNG TY TNHH SẢN XUẤT BAO BÌ VINACO | U18: =IFERROR(__xludf.DUMMYFUNCTION("""COMPUTED_VALUE"""),"Vinaco") -> Vinaco | V18: =IFERROR(__xludf.DUMMYFUNCTION("""COMPUTED_VALUE"""),"Lô B10, Đường số 1, KCN Hải Sơn (GĐ 3+4), Xã Đức Hòa Hạ, Huyện Đức Hòa, tỉnh Long An") -> Lô B10, Đường số 1, KCN Hải Sơn (GĐ 3+4), Xã Đức Hòa Hạ, Huyện Đức Hòa, tỉnh Long An | W18: =IFERROR(__xludf.DUMMYFUNCTION("""COMPUTED_VALUE"""),"1101950715") -> 1101950715 | Y18: =IFERROR(__xludf.DUMMYFUNCTION("""COMPUTED_VALUE"""),"KHO DR XANH") -> KHO DR XANH | Z18: =IFERROR(__xludf.DUMMYFUNCTION("""COMPUTED_VALUE"""),"Kho Dr. Xanh") -> Kho Dr. Xanh | AA18: =IFERROR(__xludf.DUMMYFUNCTION("""COMPUTED_VALUE"""),"Số 124 Võ Văn Kiệt, KV Bình Trung, P.Long Hòa, Q. Bình Thủy, Cần Thơ") -> Số 124 Võ Văn Kiệt, KV Bình Trung, P.Long Hòa, Q. Bình Thủy, Cần Thơ
I19: =IFERROR(__xludf.DUMMYFUNCTION("""COMPUTED_VALUE"""),"Cốc đong") -> Cốc đong | J19: =IFERROR(__xludf.DUMMYFUNCTION("""COMPUTED_VALUE"""),7.0) -> 7 | K19: =IFERROR(__xludf.DUMMYFUNCTION("""COMPUTED_VALUE"""),"Cốc đong NCC giao chung hàng với chai.") -> Cốc đong NCC giao chung hàng với chai. | L19: =IFERROR(__xludf.DUMMYFUNCTION("""COMPUTED_VALUE"""),46082.0) -> 46082 | M19: =IFERROR(__xludf.DUMMYFUNCTION("""COMPUTED_VALUE"""),TRUE) -> TRUE | T19: =IFERROR(__xludf.DUMMYFUNCTION("""COMPUTED_VALUE"""),"CÔNG TY TNHH SX TM DV HẢI BÌNH") -> CÔNG TY TNHH SX TM DV HẢI BÌNH | U19: =IFERROR(__xludf.DUMMYFUNCTION("""COMPUTED_VALUE"""),"Hải Bình") -> Hải Bình | V19: =IFERROR(__xludf.DUMMYFUNCTION("""COMPUTED_VALUE"""),"30 Võ Hoành, Phường Phú Thọ Hoà, Thành phố Hồ Chí Minh, Việt Nam") -> 30 Võ Hoành, Phường Phú Thọ Hoà, Thành phố Hồ Chí Minh, Việt Nam | W19: =IFERROR(__xludf.DUMMYFUNCTION("""COMPUTED_VALUE"""),"0302202299") -> 0302202299 | Y19: =IFERROR(__xludf.DUMMYFUNCTION("""COMPUTED_VALUE"""),"KHO B18") -> KHO B18 | Z19: =IFERROR(__xludf.DUMMYFUNCTION("""COMPUTED_VALUE"""),"Kho B18") -> Kho B18 | AA19: =IFERROR(__xludf.DUMMYFUNCTION("""COMPUTED_VALUE"""),"B18 đường dẫn cầu Cần Thơ, Quốc lộ 1A, KDC TTVH Tây Đô, Phường Cái Răng, Thành phố Cần Thơ") -> B18 đường dẫn cầu Cần Thơ, Quốc lộ 1A, KDC TTVH Tây Đô, Phường Cái Răng, Thành phố Cần Thơ
I20: =IFERROR(__xludf.DUMMYFUNCTION("""COMPUTED_VALUE"""),"Chai khác") -> Chai khác | J20: =IFERROR(__xludf.DUMMYFUNCTION("""COMPUTED_VALUE"""),15.0) -> 15 | K20: =IFERROR(__xludf.DUMMYFUNCTION("""COMPUTED_VALUE"""),"Hàng cần thanh toán trước: - Làm hồ sơ 1 ngày - Thanh toán 5 ngày - Sản xuất 7 ngày - Nhận hàng 2 ngày") -> Hàng cần thanh toán trước: - Làm hồ sơ 1 ngày - Thanh toán 5 ngày - Sản xuất 7 ngày - Nhận hàng 2 ngày | L20: =IFERROR(__xludf.DUMMYFUNCTION("""COMPUTED_VALUE"""),46082.0) -> 46082 | M20: =IFERROR(__xludf.DUMMYFUNCTION("""COMPUTED_VALUE"""),FALSE) -> FALSE | T20: =IFERROR(__xludf.DUMMYFUNCTION("""COMPUTED_VALUE"""),"CÔNG TY CP HÓA CHẤT MIỀN NAM") -> CÔNG TY CP HÓA CHẤT MIỀN NAM | U20: =IFERROR(__xludf.DUMMYFUNCTION("""COMPUTED_VALUE"""),"Hóa Chất Miền Nam") -> Hóa Chất Miền Nam | V20: =IFERROR(__xludf.DUMMYFUNCTION("""COMPUTED_VALUE"""),"137B -137C, Trần Hưng Đạo, Phường An Phú, Quận Ninh Kiều, Thành phố Cần Thơ") -> 137B -137C, Trần Hưng Đạo, Phường An Phú, Quận Ninh Kiều, Thành phố Cần Thơ | W20: =IFERROR(__xludf.DUMMYFUNCTION("""COMPUTED_VALUE"""),"1800662621") -> 1800662621 | Y20: =IFERROR(__xludf.DUMMYFUNCTION("""COMPUTED_VALUE"""),"Kho C1-2") -> Kho C1-2 | Z20: =IFERROR(__xludf.DUMMYFUNCTION("""COMPUTED_VALUE"""),"Kho C1-2") -> Kho C1-2 | AA20: =IFERROR(__xludf.DUMMYFUNCTION("""COMPUTED_VALUE"""),"Kho C1-2") -> Kho C1-2
I21: =IFERROR(__xludf.DUMMYFUNCTION("""COMPUTED_VALUE"""),"Nắp") -> Nắp | J21: =IFERROR(__xludf.DUMMYFUNCTION("""COMPUTED_VALUE"""),15.0) -> 15 | K21: =IFERROR(__xludf.DUMMYFUNCTION("""COMPUTED_VALUE"""),"Nắp NCC giao chung hàng với chai.") -> Nắp NCC giao chung hàng với chai. | L21: =IFERROR(__xludf.DUMMYFUNCTION("""COMPUTED_VALUE"""),46082.0) -> 46082 | M21: =IFERROR(__xludf.DUMMYFUNCTION("""COMPUTED_VALUE"""),FALSE) -> FALSE | T21: =IFERROR(__xludf.DUMMYFUNCTION("""COMPUTED_VALUE"""),"CÔNG TY CP QUÔC TẾ TM GROW") -> CÔNG TY CP QUÔC TẾ TM GROW | U21: =IFERROR(__xludf.DUMMYFUNCTION("""COMPUTED_VALUE"""),"Tmg") -> Tmg | V21: =IFERROR(__xludf.DUMMYFUNCTION("""COMPUTED_VALUE"""),"Trung tâm dịch vụ khu công nghiệp Amata, đường Amata, KCN Amata, Phường Long Bình, Thành phố Biên Hoà, Tỉnh Đồng Nai") -> Trung tâm dịch vụ khu công nghiệp Amata, đường Amata, KCN Amata, Phường Long Bình, Thành phố Biên Hoà, Tỉnh Đồng Nai | W21: =IFERROR(__xludf.DUMMYFUNCTION("""COMPUTED_VALUE"""),"3600630513") -> 3600630513 | Y21: =IFERROR(__xludf.DUMMYFUNCTION("""COMPUTED_VALUE"""),"KHO F49 - ICARE") -> KHO F49 - ICARE | Z21: =IFERROR(__xludf.DUMMYFUNCTION("""COMPUTED_VALUE"""),"Kho F49 - Icare") -> Kho F49 - Icare | AA21: =IFERROR(__xludf.DUMMYFUNCTION("""COMPUTED_VALUE"""),"nhà F49 (chạy qua trường lái Chiến Thắng) đường số 7, KDC Long Thịnh, Phường Phú Thứ, Cái Răng, Cần Thơ") -> nhà F49 (chạy qua trường lái Chiến Thắng) đường số 7, KDC Long Thịnh, Phường Phú Thứ, Cái Răng, Cần Thơ
I22: =IFERROR(__xludf.DUMMYFUNCTION("""COMPUTED_VALUE"""),"Cốc đong") -> Cốc đong | J22: =IFERROR(__xludf.DUMMYFUNCTION("""COMPUTED_VALUE"""),15.0) -> 15 | L22: =IFERROR(__xludf.DUMMYFUNCTION("""COMPUTED_VALUE"""),46082.0) -> 46082 | M22: =IFERROR(__xludf.DUMMYFUNCTION("""COMPUTED_VALUE"""),FALSE) -> FALSE | T22: =IFERROR(__xludf.DUMMYFUNCTION("""COMPUTED_VALUE"""),"CÔNG TY CP ĐẮC KHANG") -> CÔNG TY CP ĐẮC KHANG | U22: =IFERROR(__xludf.DUMMYFUNCTION("""COMPUTED_VALUE"""),"Đắc Khang") -> Đắc Khang | V22: =IFERROR(__xludf.DUMMYFUNCTION("""COMPUTED_VALUE"""),"482/10/28A1 Nơ Trang Long, Phường 13, Quận Bình Thạnh, Thành phố Hồ Chí Minh") -> 482/10/28A1 Nơ Trang Long, Phường 13, Quận Bình Thạnh, Thành phố Hồ Chí Minh | W22: =IFERROR(__xludf.DUMMYFUNCTION("""COMPUTED_VALUE"""),"0304714687") -> 0304714687 | Y22: =IFERROR(__xludf.DUMMYFUNCTION("""COMPUTED_VALUE"""),"KHO LAB DEGO") -> KHO LAB DEGO | Z22: =IFERROR(__xludf.DUMMYFUNCTION("""COMPUTED_VALUE"""),"Kho Lab Dego") -> Kho Lab Dego | AA22: =IFERROR(__xludf.DUMMYFUNCTION("""COMPUTED_VALUE"""),"B19 đường dẫn cầu Cần Thơ, Quốc lộ 1A, KDC TTVH Tây Đô, Phường Cái Răng, Thành phố Cần Thơ") -> B19 đường dẫn cầu Cần Thơ, Quốc lộ 1A, KDC TTVH Tây Đô, Phường Cái Răng, Thành phố Cần Thơ
I23: =IFERROR(__xludf.DUMMYFUNCTION("""COMPUTED_VALUE"""),"NL NK") -> NL NK | J23: =IFERROR(__xludf.DUMMYFUNCTION("""COMPUTED_VALUE"""),59.0) -> 59 | K23: =IFERROR(__xludf.DUMMYFUNCTION("""COMPUTED_VALUE"""),"- Làm hợp đồng với NCC cũ: 5 ngày - Chuẩn bị hàng: 14 ngày - Giao hàng 20 ngày - Nhận hàng + thông quan: 20 ngày") -> - Làm hợp đồng với NCC cũ: 5 ngày - Chuẩn bị hàng: 14 ngày - Giao hàng 20 ngày - Nhận hàng + thông quan: 20 ngày | L23: =IFERROR(__xludf.DUMMYFUNCTION("""COMPUTED_VALUE"""),46082.0) -> 46082 | M23: =IFERROR(__xludf.DUMMYFUNCTION("""COMPUTED_VALUE"""),TRUE) -> TRUE | T23: =IFERROR(__xludf.DUMMYFUNCTION("""COMPUTED_VALUE"""),"CÔNG TY TNHH SX TM DV PHÁT ĐẠI LỘC") -> CÔNG TY TNHH SX TM DV PHÁT ĐẠI LỘC | U23: =IFERROR(__xludf.DUMMYFUNCTION("""COMPUTED_VALUE"""),"Phát Đại Lộc") -> Phát Đại Lộc | V23: =IFERROR(__xludf.DUMMYFUNCTION("""COMPUTED_VALUE"""),"Số 24 Đường Hiệp Thành 48, Phường Hiệp Thành, Quận 12, Thành phố Hồ Chí Minh") -> Số 24 Đường Hiệp Thành 48, Phường Hiệp Thành, Quận 12, Thành phố Hồ Chí Minh | W23: =IFERROR(__xludf.DUMMYFUNCTION("""COMPUTED_VALUE"""),"0317409056") -> 0317409056
I24: =IFERROR(__xludf.DUMMYFUNCTION("""COMPUTED_VALUE"""),"NL Icare") -> NL Icare | J24: =IFERROR(__xludf.DUMMYFUNCTION("""COMPUTED_VALUE"""),4.0) -> 4 | K24: =IFERROR(__xludf.DUMMYFUNCTION("""COMPUTED_VALUE"""),"Trong nước, công nợ") -> Trong nước, công nợ | L24: =IFERROR(__xludf.DUMMYFUNCTION("""COMPUTED_VALUE"""),46082.0) -> 46082 | T24: =IFERROR(__xludf.DUMMYFUNCTION("""COMPUTED_VALUE"""),"CÔNG TY TNHH THƯƠNG MẠI HIỀN PHAN") -> CÔNG TY TNHH THƯƠNG MẠI HIỀN PHAN | U24: =IFERROR(__xludf.DUMMYFUNCTION("""COMPUTED_VALUE"""),"Hiền Phan") -> Hiền Phan | V24: =IFERROR(__xludf.DUMMYFUNCTION("""COMPUTED_VALUE"""),"Số 64 Lê Lăng, Phường Phú Thọ Hoà, Quận Tân Phú, Thành phố Hồ Chí Minh") -> Số 64 Lê Lăng, Phường Phú Thọ Hoà, Quận Tân Phú, Thành phố Hồ Chí Minh | W24: =IFERROR(__xludf.DUMMYFUNCTION("""COMPUTED_VALUE"""),"0305877109") -> 0305877109
I25: =IFERROR(__xludf.DUMMYFUNCTION("""COMPUTED_VALUE"""),"Xốp ( bong bóng khí)") -> Xốp ( bong bóng khí) | J25: =IFERROR(__xludf.DUMMYFUNCTION("""COMPUTED_VALUE"""),5.0) -> 5 | L25: =IFERROR(__xludf.DUMMYFUNCTION("""COMPUTED_VALUE"""),46082.0) -> 46082 | T25: =IFERROR(__xludf.DUMMYFUNCTION("""COMPUTED_VALUE"""),"CÔNG TY TNHH XNK HÓA CHẤT VẠN AN") -> CÔNG TY TNHH XNK HÓA CHẤT VẠN AN | U25: =IFERROR(__xludf.DUMMYFUNCTION("""COMPUTED_VALUE"""),"Vạn An") -> Vạn An | V25: =IFERROR(__xludf.DUMMYFUNCTION("""COMPUTED_VALUE"""),"208C Nguyễn Ngọc Nhựt, Phường Tân Quý, Quận Tân Phú, Thành phố Hồ Chí Minh") -> 208C Nguyễn Ngọc Nhựt, Phường Tân Quý, Quận Tân Phú, Thành phố Hồ Chí Minh | W25: =IFERROR(__xludf.DUMMYFUNCTION("""COMPUTED_VALUE"""),"0314845752") -> 0314845752
I26: =IFERROR(__xludf.DUMMYFUNCTION("""COMPUTED_VALUE"""),"Giấy nhiệt K100x150") -> Giấy nhiệt K100x150 | J26: =IFERROR(__xludf.DUMMYFUNCTION("""COMPUTED_VALUE"""),5.0) -> 5 | L26: =IFERROR(__xludf.DUMMYFUNCTION("""COMPUTED_VALUE"""),46082.0) -> 46082 | T26: =IFERROR(__xludf.DUMMYFUNCTION("""COMPUTED_VALUE"""),"CÔNG TY TNHH VĨNH NAM ANH") -> CÔNG TY TNHH VĨNH NAM ANH | U26: =IFERROR(__xludf.DUMMYFUNCTION("""COMPUTED_VALUE"""),"Vĩnh Nam Anh") -> Vĩnh Nam Anh | V26: =IFERROR(__xludf.DUMMYFUNCTION("""COMPUTED_VALUE"""),"65/1 Ấp 1, Bùi Công Trừng, Xã Nhị Bình, Huyện Hóc Môn, Thành phố Hồ Chí Minh") -> 65/1 Ấp 1, Bùi Công Trừng, Xã Nhị Bình, Huyện Hóc Môn, Thành phố Hồ Chí Minh | W26: =IFERROR(__xludf.DUMMYFUNCTION("""COMPUTED_VALUE"""),"0304973949") -> 0304973949
I27: =IFERROR(__xludf.DUMMYFUNCTION("""COMPUTED_VALUE"""),"HDSD Antisol") -> HDSD Antisol | J27: =IFERROR(__xludf.DUMMYFUNCTION("""COMPUTED_VALUE"""),10.0) -> 10 | L27: =IFERROR(__xludf.DUMMYFUNCTION("""COMPUTED_VALUE"""),46082.0) -> 46082 | T27: =IFERROR(__xludf.DUMMYFUNCTION("""COMPUTED_VALUE"""),"CÔNG TY TNHH KỸ THUẬT AN TOÀN MÔI TRƯỜNG HÒA PHÁT") -> CÔNG TY TNHH KỸ THUẬT AN TOÀN MÔI TRƯỜNG HÒA PHÁT | U27: =IFERROR(__xludf.DUMMYFUNCTION("""COMPUTED_VALUE"""),"Hòa Phát") -> Hòa Phát | V27: =IFERROR(__xludf.DUMMYFUNCTION("""COMPUTED_VALUE"""),"173/53 Thoại Ngọc Hầu, Phường Phú Thạnh, Quận Tân Phú, Thành phố Hồ Chí Minh") -> 173/53 Thoại Ngọc Hầu, Phường Phú Thạnh, Quận Tân Phú, Thành phố Hồ Chí Minh | W27: =IFERROR(__xludf.DUMMYFUNCTION("""COMPUTED_VALUE"""),"0312483507") -> 0312483507
